Workbook

Sheet PROJELER
B2: NO | C2: Yapılacak İş | D2: ODAK Numarası | E2: Müşteri Numarası | F2: Klasör | G2: Referans İşlerin Klasör Numaraları | H2: Yapacak / Yapan Kişi | I2: Tasarım Termin Tarihi | J2: Proje Termin Tarihi | K2: Durumu | L2: Notlar
B3: 1 | C3: MN-7955-0013 EMİCİ SI PLAKA(KÖPÜK) | H3: Mustafa Altay | I3: 46297 | K3: Devam Ediyor | L3: 90/130 SET HAZIR MALZEME BEKLENİYOR
B4: 2 | C4: Yan kapak MG trim fikstürü | H4: Ahmet Emin Gezer | K4: Tamamlandı
B5: 3 | C5: Yan kapak YS trim fikstürü | H5: Mustafa Altay | K5: Tamamlandı
B6: 4 | C6: RAM kanat analiz | H6: Ahmet Emin Gezer | I6: 46295
B7: 5 | C7: Alt kapak MG trim fikstürü | H7: Mustafa Altay | I7: 46295 | K7: Tamamlandı
B8: 6 | C8: Yıldırım çubuğu fikstür | H8: Ahmet Emin Gezer | I8: 46292 | K8: Tamamlandı
B9: 7 | C9: Blade fikstür | H9: Ahmet Emin Gezer | I9: 46292 | K9: Tamamlandı
B10: 8 | C10: Sismik fiyat teklifi çalışma | H10: Mustafa Altay | I10: 46291 | K10: Tamamlandı
B11: 9 | C11: F104 formları | H11: Proje Ortak
B12: 10 | C12: F115 konfigürasyon formları | H12: Proje Ortak
B13: 11 | C13: FMEA yapılması | H13: Proje Ortak
B14: 12 | C14: KANATCIK BOYA FIKSTUR | H14: Ahmet Emin Gezer | K14: Tamamlandı
B16: Durum Renk Kodları: | C16: Tamamlandı | D16: Devam Ediyor | E16: Beklemede | F16: Atanmadı | G16: İptal Edildi

Sheet İş Emri Takip
A1: İŞ EMRİ BİLGİLERİ | G1: ÜRETİM AŞAMALARI — Tarih girin. Her birim: parça sonraki aşamaya geçince KAPANDI. İş emri: SEVK edilince ya da KAPANIŞ tarihi girilince kapanır. | U1: REWORK | Z1: ANLIK TAKİP | AB1: Notlar | AD1: YARDIMCI SÜTUNLAR (rapor için, silmeyin)
A2: NO | B2: İş Emri No | C2: Parça / İş Adı | D2: Adet | E2: Sorumlu Kişi | F2: İş Emri Tarihi | G2: Tasarım | H2: Ply Cutter | I2: Üretim | J2: Kalite (Üretim sonrası) | K2: Talaşlı | L2: Kalite (Talaşlı sonrası) | M2: Montaj | N2: Kalite (Montaj sonrası) | O2: Boya | P2: Kalite (Boya sonrası) | Q2: Yarı Mamül | R2: KM | S2: Sevk | T2: KAPANIŞ (iş bitti) | U2: Rework Adedi | V2: Rework Nedeni | W2: Rework Açıklaması | X2: Rework Açılış Tarihi | Y2: Rework Bitiş Tarihi | Z2: Güncel Durum | AA2: Geçen Süre (gün) | AD2: Süre: Tasarım | AE2: Süre: Ply Cutter | AF2: Süre: Üretim | AG2: Süre: Kalite (Üretim sonrası) | AH2: Süre: Talaşlı | AI2: Süre: Kalite (Talaşlı sonrası) | AJ2: Süre: Montaj | AK2: Süre: Kalite (Montaj sonrası) | AL2: Süre: Boya | AM2: Süre: Kalite (Boya sonrası) | AN2: Süre: Yarı Mamül | AO2: Süre: KM | AP2: Son aşamada bekleme | AQ2: Kapanış: Tasarım | AR2: Kapanış: Ply Cutter | AS2: Kapanış: Üretim | AT2: Kapanış: Kalite (Üretim sonrası) | AU2: Kapanış: Talaşlı | AV2: Kapanış: Kalite (Talaşlı sonrası) | AW2: Kapanış: Montaj | AX2: Kapanış: Kalite (Montaj sonrası) | AY2: Kapanış: Boya | AZ2: Kapanış: Kalite (Boya sonrası) | BA2: Kapanış: Yarı Mamül | BB2: Kapanış: KM | BC2: Bitiş (sevk/kapanış)
A3: =IF(B3="","",ROW()-2) -> 1 | B3: M42986 | C3: SOM0010-B - 1 - SOM SOL KANAT LAY-UP | D3: =IFERROR(VALUE(TRIM(MID(C3,FIND(" - ",C3)+3,FIND(" - ",C3,FIND(" - ",C3)+3)-FIND(" - ",C3)-3))),"") -> 1 | E3: AYÇA GÖK | F3: 46288 | I3: 46288 | J3: 46290 | T3: 46291 | Z3: =IF(B3="","",IF(S3<>"","Sevk Edildi",IF(AND(X3<>"",Y3=""),"Reworkte",IF(T3<>"","Kapandı"&IF(COUNT(G3:R3)=0,""," – "&LOOKUP(2,1/(G3:R3=MAX(G3:R3)),{"Tasarım","Ply Cutter","Üretim","Kalite (Üretim sonrası)","Talaşlı","Kalite (Talaşlı sonrası)","Montaj","Kalite (Montaj sonrası)","Boya","Kalite (Boya sonrası)","Yarı Mamül","KM"})),IF(COUNT(G3:R3)=0,"Başlamadı",LOOKUP(2,1/(G3:R3=MAX(G3:R3)),{"Tasarımda","Ply Cutter'da","Üretimde","Kalitede (Üretim sonrası)","Talaşlıda","Kalitede (Talaşlı sonrası)","Montajda","Kalitede (Montaj sonrası)","Boyada","Kalitede (Boya sonrası)","Yarı Mamülde","KM'de"})))))) -> Kapandı – Kalite (Üretim sonrası) | AA3: =IF(OR(B3="",F3=""),"",IFERROR(IF(S3<>"",S3-F3,IF(T3<>"",T3-F3,TODAY()-F3)),"")) -> 3 | AB3: Örnek satırdır, silinebilir. | AD3: =IF(OR($B3="",NOT(ISNUMBER(G3))),"",IF(COUNTIF(H3:$T3,G3)>0,0,IF(COUNTIF($G3:$T3,">"&G3)=0,"",SMALL($G3:$T3,COUNTIF($G3:$T3,"<="&G3)+1)-G3))) | AE3: =IF(OR($B3="",NOT(ISNUMBER(H3))),"",IF(COUNTIF(I3:$T3,H3)>0,0,IF(COUNTIF($G3:$T3,">"&H3)=0,"",SMALL($G3:$T3,COUNTIF($G3:$T3,"<="&H3)+1)-H3))) | AF3: =IF(OR($B3="",NOT(ISNUMBER(I3))),"",IF(COUNTIF(J3:$T3,I3)>0,0,IF(COUNTIF($G3:$T3,">"&I3)=0,"",SMALL($G3:$T3,COUNTIF($G3:$T3,"<="&I3)+1)-I3))) -> 2 | AG3: =IF(OR($B3="",NOT(ISNUMBER(J3))),"",IF(COUNTIF(K3:$T3,J3)>0,0,IF(COUNTIF($G3:$T3,">"&J3)=0,"",SMALL($G3:$T3,COUNTIF($G3:$T3,"<="&J3)+1)-J3))) -> 1 | AH3: =IF(OR($B3="",NOT(ISNUMBER(K3))),"",IF(COUNTIF(L3:$T3,K3)>0,0,IF(COUNTIF($G3:$T3,">"&K3)=0,"",SMALL($G3:$T3,COUNTIF($G3:$T3,"<="&K3)+1)-K3))) | AI3: =IF(OR($B3="",NOT(ISNUMBER(L3))),"",IF(COUNTIF(M3:$T3,L3)>0,0,IF(COUNTIF($G3:$T3,">"&L3)=0,"",SMALL($G3:$T3,COUNTIF($G3:$T3,"<="&L3)+1)-L3))) | AJ3: =IF(OR($B3="",NOT(ISNUMBER(M3))),"",IF(COUNTIF(N3:$T3,M3)>0,0,IF(COUNTIF($G3:$T3,">"&M3)=0,"",SMALL($G3:$T3,COUNTIF($G3:$T3,"<="&M3)+1)-M3))) | AK3: =IF(OR($B3="",NOT(ISNUMBER(N3))),"",IF(COUNTIF(O3:$T3,N3)>0,0,IF(COUNTIF($G3:$T3,">"&N3)=0,"",SMALL($G3:$T3,COUNTIF($G3:$T3,"<="&N3)+1)-N3))) | ... AO3: =IF(OR($B3="",NOT(ISNUMBER(R3))),"",IF(COUNTIF(S3:$T3,R3)>0,0,IF(COUNTIF($G3:$T3,">"&R3)=0,"",SMALL($G3:$T3,COUNTIF($G3:$T3,"<="&R3)+1)-R3))) | AP3: =IF(OR($B3="",Z3="",Z3="Başlamadı",Z3="Sevk Edildi",Z3="Reworkte",LEFT(Z3,7)="Kapandı"),0,TODAY()-MAX($G3:$R3)) -> 0 | AQ3: =IF(AND(ISNUMBER(G3),ISNUMBER(AD3)),G3+AD3,"") | AR3: =IF(AND(ISNUMBER(H3),ISNUMBER(AE3)),H3+AE3,"") | AS3: =IF(AND(ISNUMBER(I3),ISNUMBER(AF3)),I3+AF3,"") -> 46290 | AT3: =IF(AND(ISNUMBER(J3),ISNUMBER(AG3)),J3+AG3,"") -> 46291 | AU3: =IF(AND(ISNUMBER(K3),ISNUMBER(AH3)),K3+AH3,"") | AV3: =IF(AND(ISNUMBER(L3),ISNUMBER(AI3)),L3+AI3,"") | AW3: =IF(AND(ISNUMBER(M3),ISNUMBER(AJ3)),M3+AJ3,"") | AX3: =IF(AND(ISNUMBER(N3),ISNUMBER(AK3)),N3+AK3,"") | ... BB3: =IF(AND(ISNUMBER(R3),ISNUMBER(AO3)),R3+AO3,"") | BC3: =IF(AND(S3="",T3=""),"",MIN(S3,T3)) -> 46291
A4: =IF(B4="","",ROW()-2) -> 2 | B4: M42987 | C4: 2020-007-B - 1 - HF AYAK SERIM | D4: =IFERROR(VALUE(TRIM(MID(C4,FIND(" - ",C4)+3,FIND(" - ",C4,FIND(" - ",C4)+3)-FIND(" - ",C4)-3))),"") -> 1 | E4: AYÇA GÖK | F4: 46288 | I4: 46288 | J4: 46290 | Q4: 46291 | T4: 46291 | Z4: =IF(B4="","",IF(S4<>"","Sevk Edildi",IF(AND(X4<>"",Y4=""),"Reworkte",IF(T4<>"","Kapandı"&IF(COUNT(G4:R4)=0,""," – "&LOOKUP(2,1/(G4:R4=MAX(G4:R4)),{"Tasarım","Ply Cutter","Üretim","Kalite (Üretim sonrası)","Talaşlı","Kalite (Talaşlı sonrası)","Montaj","Kalite (Montaj sonrası)","Boya","Kalite (Boya sonrası)","Yarı Mamül","KM"})),IF(COUNT(G4:R4)=0,"Başlamadı",LOOKUP(2,1/(G4:R4=MAX(G4:R4)),{"Tasarımda","Ply Cutter'da","Üretimde","Kalitede (Üretim sonrası)","Talaşlıda","Kalitede (Talaşlı sonrası)","Montajda","Kalitede (Montaj sonrası)","Boyada","Kalitede (Boya sonrası)","Yarı Mamülde","KM'de"})))))) -> Kapandı – Yarı Mamül | AA4: =IF(OR(B4="",F4=""),"",IFERROR(IF(S4<>"",S4-F4,IF(T4<>"",T4-F4,TODAY()-F4)),"")) -> 3 | AD4: =IF(OR($B4="",NOT(ISNUMBER(G4))),"",IF(COUNTIF(H4:$T4,G4)>0,0,IF(COUNTIF($G4:$T4,">"&G4)=0,"",SMALL($G4:$T4,COUNTIF($G4:$T4,"<="&G4)+1)-G4))) | AE4: =IF(OR($B4="",NOT(ISNUMBER(H4))),"",IF(COUNTIF(I4:$T4,H4)>0,0,IF(COUNTIF($G4:$T4,">"&H4)=0,"",SMALL($G4:$T4,COUNTIF($G4:$T4,"<="&H4)+1)-H4))) | AF4: =IF(OR($B4="",NOT(ISNUMBER(I4))),"",IF(COUNTIF(J4:$T4,I4)>0,0,IF(COUNTIF($G4:$T4,">"&I4)=0,"",SMALL($G4:$T4,COUNTIF($G4:$T4,"<="&I4)+1)-I4))) -> 2 | AG4: =IF(OR($B4="",NOT(ISNUMBER(J4))),"",IF(COUNTIF(K4:$T4,J4)>0,0,IF(COUNTIF($G4:$T4,">"&J4)=0,"",SMALL($G4:$T4,COUNTIF($G4:$T4,"<="&J4)+1)-J4))) -> 1 | AH4: =IF(OR($B4="",NOT(ISNUMBER(K4))),"",IF(COUNTIF(L4:$T4,K4)>0,0,IF(COUNTIF($G4:$T4,">"&K4)=0,"",SMALL($G4:$T4,COUNTIF($G4:$T4,"<="&K4)+1)-K4))) | AI4: =IF(OR($B4="",NOT(ISNUMBER(L4))),"",IF(COUNTIF(M4:$T4,L4)>0,0,IF(COUNTIF($G4:$T4,">"&L4)=0,"",SMALL($G4:$T4,COUNTIF($G4:$T4,"<="&L4)+1)-L4))) | AJ4: =IF(OR($B4="",NOT(ISNUMBER(M4))),"",IF(COUNTIF(N4:$T4,M4)>0,0,IF(COUNTIF($G4:$T4,">"&M4)=0,"",SMALL($G4:$T4,COUNTIF($G4:$T4,"<="&M4)+1)-M4))) | AK4: =IF(OR($B4="",NOT(ISNUMBER(N4))),"",IF(COUNTIF(O4:$T4,N4)>0,0,IF(COUNTIF($G4:$T4,">"&N4)=0,"",SMALL($G4:$T4,COUNTIF($G4:$T4,"<="&N4)+1)-N4))) | ... AO4: =IF(OR($B4="",NOT(ISNUMBER(R4))),"",IF(COUNTIF(S4:$T4,R4)>0,0,IF(COUNTIF($G4:$T4,">"&R4)=0,"",SMALL($G4:$T4,COUNTIF($G4:$T4,"<="&R4)+1)-R4))) | AP4: =IF(OR($B4="",Z4="",Z4="Başlamadı",Z4="Sevk Edildi",Z4="Reworkte",LEFT(Z4,7)="Kapandı"),0,TODAY()-MAX($G4:$R4)) -> 0 | AQ4: =IF(AND(ISNUMBER(G4),ISNUMBER(AD4)),G4+AD4,"") | AR4: =IF(AND(ISNUMBER(H4),ISNUMBER(AE4)),H4+AE4,"") | AS4: =IF(AND(ISNUMBER(I4),ISNUMBER(AF4)),I4+AF4,"") -> 46290 | AT4: =IF(AND(ISNUMBER(J4),ISNUMBER(AG4)),J4+AG4,"") -> 46291 | AU4: =IF(AND(ISNUMBER(K4),ISNUMBER(AH4)),K4+AH4,"") | AV4: =IF(AND(ISNUMBER(L4),ISNUMBER(AI4)),L4+AI4,"") | AW4: =IF(AND(ISNUMBER(M4),ISNUMBER(AJ4)),M4+AJ4,"") | AX4: =IF(AND(ISNUMBER(N4),ISNUMBER(AK4)),N4+AK4,"") | ... BB4: =IF(AND(ISNUMBER(R4),ISNUMBER(AO4)),R4+AO4,"") | BC4: =IF(AND(S4="",T4=""),"",MIN(S4,T4)) -> 46291
A5: =IF(B5="","",ROW()-2) -> 3 | B5: M42988 | C5: 2020-007-B - 1 - HF AYAK SERIM | D5: =IFERROR(VALUE(TRIM(MID(C5,FIND(" - ",C5)+3,FIND(" - ",C5,FIND(" - ",C5)+3)-FIND(" - ",C5)-3))),"") -> 1 | E5: AYÇA GÖK | F5: 46288 | I5: 46288 | J5: 46290 | Q5: 46291 | T5: 46291 | Z5: =IF(B5="","",IF(S5<>"","Sevk Edildi",IF(AND(X5<>"",Y5=""),"Reworkte",IF(T5<>"","Kapandı"&IF(COUNT(G5:R5)=0,""," – "&LOOKUP(2,1/(G5:R5=MAX(G5:R5)),{"Tasarım","Ply Cutter","Üretim","Kalite (Üretim sonrası)","Talaşlı","Kalite (Talaşlı sonrası)","Montaj","Kalite (Montaj sonrası)","Boya","Kalite (Boya sonrası)","Yarı Mamül","KM"})),IF(COUNT(G5:R5)=0,"Başlamadı",LOOKUP(2,1/(G5:R5=MAX(G5:R5)),{"Tasarımda","Ply Cutter'da","Üretimde","Kalitede (Üretim sonrası)","Talaşlıda","Kalitede (Talaşlı sonrası)","Montajda","Kalitede (Montaj sonrası)","Boyada","Kalitede (Boya sonrası)","Yarı Mamülde","KM'de"})))))) -> Kapandı – Yarı Mamül | AA5: =IF(OR(B5="",F5=""),"",IFERROR(IF(S5<>"",S5-F5,IF(T5<>"",T5-F5,TODAY()-F5)),"")) -> 3 | AD5: =IF(OR($B5="",NOT(ISNUMBER(G5))),"",IF(COUNTIF(H5:$T5,G5)>0,0,IF(COUNTIF($G5:$T5,">"&G5)=0,"",SMALL($G5:$T5,COUNTIF($G5:$T5,"<="&G5)+1)-G5))) | AE5: =IF(OR($B5="",NOT(ISNUMBER(H5))),"",IF(COUNTIF(I5:$T5,H5)>0,0,IF(COUNTIF($G5:$T5,">"&H5)=0,"",SMALL($G5:$T5,COUNTIF($G5:$T5,"<="&H5)+1)-H5))) | AF5: =IF(OR($B5="",NOT(ISNUMBER(I5))),"",IF(COUNTIF(J5:$T5,I5)>0,0,IF(COUNTIF($G5:$T5,">"&I5)=0,"",SMALL($G5:$T5,COUNTIF($G5:$T5,"<="&I5)+1)-I5))) -> 2 | AG5: =IF(OR($B5="",NOT(ISNUMBER(J5))),"",IF(COUNTIF(K5:$T5,J5)>0,0,IF(COUNTIF($G5:$T5,">"&J5)=0,"",SMALL($G5:$T5,COUNTIF($G5:$T5,"<="&J5)+1)-J5))) -> 1 | AH5: =IF(OR($B5="",NOT(ISNUMBER(K5))),"",IF(COUNTIF(L5:$T5,K5)>0,0,IF(COUNTIF($G5:$T5,">"&K5)=0,"",SMALL($G5:$T5,COUNTIF($G5:$T5,"<="&K5)+1)-K5))) | AI5: =IF(OR($B5="",NOT(ISNUMBER(L5))),"",IF(COUNTIF(M5:$T5,L5)>0,0,IF(COUNTIF($G5:$T5,">"&L5)=0,"",SMALL($G5:$T5,COUNTIF($G5:$T5,"<="&L5)+1)-L5))) | AJ5: =IF(OR($B5="",NOT(ISNUMBER(M5))),"",IF(COUNTIF(N5:$T5,M5)>0,0,IF(COUNTIF($G5:$T5,">"&M5)=0,"",SMALL($G5:$T5,COUNTIF($G5:$T5,"<="&M5)+1)-M5))) | AK5: =IF(OR($B5="",NOT(ISNUMBER(N5))),"",IF(COUNTIF(O5:$T5,N5)>0,0,IF(COUNTIF($G5:$T5,">"&N5)=0,"",SMALL($G5:$T5,COUNTIF($G5:$T5,"<="&N5)+1)-N5))) | ... AO5: =IF(OR($B5="",NOT(ISNUMBER(R5))),"",IF(COUNTIF(S5:$T5,R5)>0,0,IF(COUNTIF($G5:$T5,">"&R5)=0,"",SMALL($G5:$T5,COUNTIF($G5:$T5,"<="&R5)+1)-R5))) | AP5: =IF(OR($B5="",Z5="",Z5="Başlamadı",Z5="Sevk Edildi",Z5="Reworkte",LEFT(Z5,7)="Kapandı"),0,TODAY()-MAX($G5:$R5)) -> 0 | AQ5: =IF(AND(ISNUMBER(G5),ISNUMBER(AD5)),G5+AD5,"") | AR5: =IF(AND(ISNUMBER(H5),ISNUMBER(AE5)),H5+AE5,"") | AS5: =IF(AND(ISNUMBER(I5),ISNUMBER(AF5)),I5+AF5,"") -> 46290 | AT5: =IF(AND(ISNUMBER(J5),ISNUMBER(AG5)),J5+AG5,"") -> 46291 | AU5: =IF(AND(ISNUMBER(K5),ISNUMBER(AH5)),K5+AH5,"") | AV5: =IF(AND(ISNUMBER(L5),ISNUMBER(AI5)),L5+AI5,"") | AW5: =IF(AND(ISNUMBER(M5),ISNUMBER(AJ5)),M5+AJ5,"") | AX5: =IF(AND(ISNUMBER(N5),ISNUMBER(AK5)),N5+AK5,"") | ... BB5: =IF(AND(ISNUMBER(R5),ISNUMBER(AO5)),R5+AO5,"") | BC5: =IF(AND(S5="",T5=""),"",MIN(S5,T5)) -> 46291
A6: =IF(B6="","",ROW()-2) -> 4 | B6: M42989 | C6: MN-0000-4163-B - 5 - BORU KMPZT YILDIRIM KORUMA GU | D6: =IFERROR(VALUE(TRIM(MID(C6,FIND(" - ",C6)+3,FIND(" - ",C6,FIND(" - ",C6)+3)-FIND(" - ",C6)-3))),"") -> 5 | E6: AYÇA GÖK | F6: 46288 | I6: 46288 | J6: 46291 | T6: 46291 | Z6: =IF(B6="","",IF(S6<>"","Sevk Edildi",IF(AND(X6<>"",Y6=""),"Reworkte",IF(T6<>"","Kapandı"&IF(COUNT(G6:R6)=0,""," – "&LOOKUP(2,1/(G6:R6=MAX(G6:R6)),{"Tasarım","Ply Cutter","Üretim","Kalite (Üretim sonrası)","Talaşlı","Kalite (Talaşlı sonrası)","Montaj","Kalite (Montaj sonrası)","Boya","Kalite (Boya sonrası)","Yarı Mamül","KM"})),IF(COUNT(G6:R6)=0,"Başlamadı",LOOKUP(2,1/(G6:R6=MAX(G6:R6)),{"Tasarımda","Ply Cutter'da","Üretimde","Kalitede (Üretim sonrası)","Talaşlıda","Kalitede (Talaşlı sonrası)","Montajda","Kalitede (Montaj sonrası)","Boyada","Kalitede (Boya sonrası)","Yarı Mamülde","KM'de"})))))) -> Kapandı – Kalite (Üretim sonrası) | AA6: =IF(OR(B6="",F6=""),"",IFERROR(IF(S6<>"",S6-F6,IF(T6<>"",T6-F6,TODAY()-F6)),"")) -> 3 | AB6: 18 ADETTEN 7 ADET MONTAJDA | AD6: =IF(OR($B6="",NOT(ISNUMBER(G6))),"",IF(COUNTIF(H6:$T6,G6)>0,0,IF(COUNTIF($G6:$T6,">"&G6)=0,"",SMALL($G6:$T6,COUNTIF($G6:$T6,"<="&G6)+1)-G6))) | AE6: =IF(OR($B6="",NOT(ISNUMBER(H6))),"",IF(COUNTIF(I6:$T6,H6)>0,0,IF(COUNTIF($G6:$T6,">"&H6)=0,"",SMALL($G6:$T6,COUNTIF($G6:$T6,"<="&H6)+1)-H6))) | AF6: =IF(OR($B6="",NOT(ISNUMBER(I6))),"",IF(COUNTIF(J6:$T6,I6)>0,0,IF(COUNTIF($G6:$T6,">"&I6)=0,"",SMALL($G6:$T6,COUNTIF($G6:$T6,"<="&I6)+1)-I6))) -> 3 | AG6: =IF(OR($B6="",NOT(ISNUMBER(J6))),"",IF(COUNTIF(K6:$T6,J6)>0,0,IF(COUNTIF($G6:$T6,">"&J6)=0,"",SMALL($G6:$T6,COUNTIF($G6:$T6,"<="&J6)+1)-J6))) -> 0 | AH6: =IF(OR($B6="",NOT(ISNUMBER(K6))),"",IF(COUNTIF(L6:$T6,K6)>0,0,IF(COUNTIF($G6:$T6,">"&K6)=0,"",SMALL($G6:$T6,COUNTIF($G6:$T6,"<="&K6)+1)-K6))) | AI6: =IF(OR($B6="",NOT(ISNUMBER(L6))),"",IF(COUNTIF(M6:$T6,L6)>0,0,IF(COUNTIF($G6:$T6,">"&L6)=0,"",SMALL($G6:$T6,COUNTIF($G6:$T6,"<="&L6)+1)-L6))) | AJ6: =IF(OR($B6="",NOT(ISNUMBER(M6))),"",IF(COUNTIF(N6:$T6,M6)>0,0,IF(COUNTIF($G6:$T6,">"&M6)=0,"",SMALL($G6:$T6,COUNTIF($G6:$T6,"<="&M6)+1)-M6))) | AK6: =IF(OR($B6="",NOT(ISNUMBER(N6))),"",IF(COUNTIF(O6:$T6,N6)>0,0,IF(COUNTIF($G6:$T6,">"&N6)=0,"",SMALL($G6:$T6,COUNTIF($G6:$T6,"<="&N6)+1)-N6))) | ... AO6: =IF(OR($B6="",NOT(ISNUMBER(R6))),"",IF(COUNTIF(S6:$T6,R6)>0,0,IF(COUNTIF($G6:$T6,">"&R6)=0,"",SMALL($G6:$T6,COUNTIF($G6:$T6,"<="&R6)+1)-R6))) | AP6: =IF(OR($B6="",Z6="",Z6="Başlamadı",Z6="Sevk Edildi",Z6="Reworkte",LEFT(Z6,7)="Kapandı"),0,TODAY()-MAX($G6:$R6)) -> 0 | AQ6: =IF(AND(ISNUMBER(G6),ISNUMBER(AD6)),G6+AD6,"") | AR6: =IF(AND(ISNUMBER(H6),ISNUMBER(AE6)),H6+AE6,"") | AS6: =IF(AND(ISNUMBER(I6),ISNUMBER(AF6)),I6+AF6,"") -> 46291 | AT6: =IF(AND(ISNUMBER(J6),ISNUMBER(AG6)),J6+AG6,"") -> 46291 | AU6: =IF(AND(ISNUMBER(K6),ISNUMBER(AH6)),K6+AH6,"") | AV6: =IF(AND(ISNUMBER(L6),ISNUMBER(AI6)),L6+AI6,"") | AW6: =IF(AND(ISNUMBER(M6),ISNUMBER(AJ6)),M6+AJ6,"") | AX6: =IF(AND(ISNUMBER(N6),ISNUMBER(AK6)),N6+AK6,"") | ... BB6: =IF(AND(ISNUMBER(R6),ISNUMBER(AO6)),R6+AO6,"") | BC6: =IF(AND(S6="",T6=""),"",MIN(S6,T6)) -> 46291
A7: =IF(B7="","",ROW()-2) -> 5 | B7: M42990 | C7: MN-0000-4163-B - 5 - BORU KMPZT YILDIRIM KORUMA GU | D7: =IFERROR(VALUE(TRIM(MID(C7,FIND(" - ",C7)+3,FIND(" - ",C7,FIND(" - ",C7)+3)-FIND(" - ",C7)-3))),"") -> 5 | E7: AYÇA GÖK | F7: 46288 | I7: 46288 | J7: 46291 | T7: 46291 | Z7: =IF(B7="","",IF(S7<>"","Sevk Edildi",IF(AND(X7<>"",Y7=""),"Reworkte",IF(T7<>"","Kapandı"&IF(COUNT(G7:R7)=0,""," – "&LOOKUP(2,1/(G7:R7=MAX(G7:R7)),{"Tasarım","Ply Cutter","Üretim","Kalite (Üretim sonrası)","Talaşlı","Kalite (Talaşlı sonrası)","Montaj","Kalite (Montaj sonrası)","Boya","Kalite (Boya sonrası)","Yarı Mamül","KM"})),IF(COUNT(G7:R7)=0,"Başlamadı",LOOKUP(2,1/(G7:R7=MAX(G7:R7)),{"Tasarımda","Ply Cutter'da","Üretimde","Kalitede (Üretim sonrası)","Talaşlıda","Kalitede (Talaşlı sonrası)","Montajda","Kalitede (Montaj sonrası)","Boyada","Kalitede (Boya sonrası)","Yarı Mamülde","KM'de"})))))) -> Kapandı – Kalite (Üretim sonrası) | AA7: =IF(OR(B7="",F7=""),"",IFERROR(IF(S7<>"",S7-F7,IF(T7<>"",T7-F7,TODAY()-F7)),"")) -> 3 | AB7: 9 ADET YÜZEY İŞLEMİNDE | AD7: =IF(OR($B7="",NOT(ISNUMBER(G7))),"",IF(COUNTIF(H7:$T7,G7)>0,0,IF(COUNTIF($G7:$T7,">"&G7)=0,"",SMALL($G7:$T7,COUNTIF($G7:$T7,"<="&G7)+1)-G7))) | AE7: =IF(OR($B7="",NOT(ISNUMBER(H7))),"",IF(COUNTIF(I7:$T7,H7)>0,0,IF(COUNTIF($G7:$T7,">"&H7)=0,"",SMALL($G7:$T7,COUNTIF($G7:$T7,"<="&H7)+1)-H7))) | AF7: =IF(OR($B7="",NOT(ISNUMBER(I7))),"",IF(COUNTIF(J7:$T7,I7)>0,0,IF(COUNTIF($G7:$T7,">"&I7)=0,"",SMALL($G7:$T7,COUNTIF($G7:$T7,"<="&I7)+1)-I7))) -> 3 | AG7: =IF(OR($B7="",NOT(ISNUMBER(J7))),"",IF(COUNTIF(K7:$T7,J7)>0,0,IF(COUNTIF($G7:$T7,">"&J7)=0,"",SMALL($G7:$T7,COUNTIF($G7:$T7,"<="&J7)+1)-J7))) -> 0 | AH7: =IF(OR($B7="",NOT(ISNUMBER(K7))),"",IF(COUNTIF(L7:$T7,K7)>0,0,IF(COUNTIF($G7:$T7,">"&K7)=0,"",SMALL($G7:$T7,COUNTIF($G7:$T7,"<="&K7)+1)-K7))) | AI7: =IF(OR($B7="",NOT(ISNUMBER(L7))),"",IF(COUNTIF(M7:$T7,L7)>0,0,IF(COUNTIF($G7:$T7,">"&L7)=0,"",SMALL($G7:$T7,COUNTIF($G7:$T7,"<="&L7)+1)-L7))) | AJ7: =IF(OR($B7="",NOT(ISNUMBER(M7))),"",IF(COUNTIF(N7:$T7,M7)>0,0,IF(COUNTIF($G7:$T7,">"&M7)=0,"",SMALL($G7:$T7,COUNTIF($G7:$T7,"<="&M7)+1)-M7))) | AK7: =IF(OR($B7="",NOT(ISNUMBER(N7))),"",IF(COUNTIF(O7:$T7,N7)>0,0,IF(COUNTIF($G7:$T7,">"&N7)=0,"",SMALL($G7:$T7,COUNTIF($G7:$T7,"<="&N7)+1)-N7))) | ... AO7: =IF(OR($B7="",NOT(ISNUMBER(R7))),"",IF(COUNTIF(S7:$T7,R7)>0,0,IF(COUNTIF($G7:$T7,">"&R7)=0,"",SMALL($G7:$T7,COUNTIF($G7:$T7,"<="&R7)+1)-R7))) | AP7: =IF(OR($B7="",Z7="",Z7="Başlamadı",Z7="Sevk Edildi",Z7="Reworkte",LEFT(Z7,7)="Kapandı"),0,TODAY()-MAX($G7:$R7)) -> 0 | AQ7: =IF(AND(ISNUMBER(G7),ISNUMBER(AD7)),G7+AD7,"") | AR7: =IF(AND(ISNUMBER(H7),ISNUMBER(AE7)),H7+AE7,"") | AS7: =IF(AND(ISNUMBER(I7),ISNUMBER(AF7)),I7+AF7,"") -> 46291 | AT7: =IF(AND(ISNUMBER(J7),ISNUMBER(AG7)),J7+AG7,"") -> 46291 | AU7: =IF(AND(ISNUMBER(K7),ISNUMBER(AH7)),K7+AH7,"") | AV7: =IF(AND(ISNUMBER(L7),ISNUMBER(AI7)),L7+AI7,"") | AW7: =IF(AND(ISNUMBER(M7),ISNUMBER(AJ7)),M7+AJ7,"") | AX7: =IF(AND(ISNUMBER(N7),ISNUMBER(AK7)),N7+AK7,"") | ... BB7: =IF(AND(ISNUMBER(R7),ISNUMBER(AO7)),R7+AO7,"") | BC7: =IF(AND(S7="",T7=""),"",MIN(S7,T7)) -> 46291
A8: =IF(B8="","",ROW()-2) -> 6 | B8: M42992 | C8: MN-7516-0002-B - 1 - RADOM ANTEN YASSI KUCUK PGR S | D8: =IFERROR(VALUE(TRIM(MID(C8,FIND(" - ",C8)+3,FIND(" - ",C8,FIND(" - ",C8)+3)-FIND(" - ",C8)-3))),"") -> 1 | E8: AYÇA GÖK | F8: 46288 | I8: 46288 | J8: 46290 | Q8: 46291 | T8: 46291 | Z8: =IF(B8="","",IF(S8<>"","Sevk Edildi",IF(AND(X8<>"",Y8=""),"Reworkte",IF(T8<>"","Kapandı"&IF(COUNT(G8:R8)=0,""," – "&LOOKUP(2,1/(G8:R8=MAX(G8:R8)),{"Tasarım","Ply Cutter","Üretim","Kalite (Üretim sonrası)","Talaşlı","Kalite (Talaşlı sonrası)","Montaj","Kalite (Montaj sonrası)","Boya","Kalite (Boya sonrası)","Yarı Mamül","KM"})),IF(COUNT(G8:R8)=0,"Başlamadı",LOOKUP(2,1/(G8:R8=MAX(G8:R8)),{"Tasarımda","Ply Cutter'da","Üretimde","Kalitede (Üretim sonrası)","Talaşlıda","Kalitede (Talaşlı sonrası)","Montajda","Kalitede (Montaj sonrası)","Boyada","Kalitede (Boya sonrası)","Yarı Mamülde","KM'de"})))))) -> Kapandı – Yarı Mamül | AA8: =IF(OR(B8="",F8=""),"",IFERROR(IF(S8<>"",S8-F8,IF(T8<>"",T8-F8,TODAY()-F8)),"")) -> 3 | AD8: =IF(OR($B8="",NOT(ISNUMBER(G8))),"",IF(COUNTIF(H8:$T8,G8)>0,0,IF(COUNTIF($G8:$T8,">"&G8)=0,"",SMALL($G8:$T8,COUNTIF($G8:$T8,"<="&G8)+1)-G8))) | AE8: =IF(OR($B8="",NOT(ISNUMBER(H8))),"",IF(COUNTIF(I8:$T8,H8)>0,0,IF(COUNTIF($G8:$T8,">"&H8)=0,"",SMALL($G8:$T8,COUNTIF($G8:$T8,"<="&H8)+1)-H8))) | AF8: =IF(OR($B8="",NOT(ISNUMBER(I8))),"",IF(COUNTIF(J8:$T8,I8)>0,0,IF(COUNTIF($G8:$T8,">"&I8)=0,"",SMALL($G8:$T8,COUNTIF($G8:$T8,"<="&I8)+1)-I8))) -> 2 | AG8: =IF(OR($B8="",NOT(ISNUMBER(J8))),"",IF(COUNTIF(K8:$T8,J8)>0,0,IF(COUNTIF($G8:$T8,">"&J8)=0,"",SMALL($G8:$T8,COUNTIF($G8:$T8,"<="&J8)+1)-J8))) -> 1 | AH8: =IF(OR($B8="",NOT(ISNUMBER(K8))),"",IF(COUNTIF(L8:$T8,K8)>0,0,IF(COUNTIF($G8:$T8,">"&K8)=0,"",SMALL($G8:$T8,COUNTIF($G8:$T8,"<="&K8)+1)-K8))) | AI8: =IF(OR($B8="",NOT(ISNUMBER(L8))),"",IF(COUNTIF(M8:$T8,L8)>0,0,IF(COUNTIF($G8:$T8,">"&L8)=0,"",SMALL($G8:$T8,COUNTIF($G8:$T8,"<="&L8)+1)-L8))) | AJ8: =IF(OR($B8="",NOT(ISNUMBER(M8))),"",IF(COUNTIF(N8:$T8,M8)>0,0,IF(COUNTIF($G8:$T8,">"&M8)=0,"",SMALL($G8:$T8,COUNTIF($G8:$T8,"<="&M8)+1)-M8))) | AK8: =IF(OR($B8="",NOT(ISNUMBER(N8))),"",IF(COUNTIF(O8:$T8,N8)>0,0,IF(COUNTIF($G8:$T8,">"&N8)=0,"",SMALL($G8:$T8,COUNTIF($G8:$T8,"<="&N8)+1)-N8))) | ... AO8: =IF(OR($B8="",NOT(ISNUMBER(R8))),"",IF(COUNTIF(S8:$T8,R8)>0,0,IF(COUNTIF($G8:$T8,">"&R8)=0,"",SMALL($G8:$T8,COUNTIF($G8:$T8,"<="&R8)+1)-R8))) | AP8: =IF(OR($B8="",Z8="",Z8="Başlamadı",Z8="Sevk Edildi",Z8="Reworkte",LEFT(Z8,7)="Kapandı"),0,TODAY()-MAX($G8:$R8)) -> 0 | AQ8: =IF(AND(ISNUMBER(G8),ISNUMBER(AD8)),G8+AD8,"") | AR8: =IF(AND(ISNUMBER(H8),ISNUMBER(AE8)),H8+AE8,"") | AS8: =IF(AND(ISNUMBER(I8),ISNUMBER(AF8)),I8+AF8,"") -> 46290 | AT8: =IF(AND(ISNUMBER(J8),ISNUMBER(AG8)),J8+AG8,"") -> 46291 | AU8: =IF(AND(ISNUMBER(K8),ISNUMBER(AH8)),K8+AH8,"") | AV8: =IF(AND(ISNUMBER(L8),ISNUMBER(AI8)),L8+AI8,"") | AW8: =IF(AND(ISNUMBER(M8),ISNUMBER(AJ8)),M8+AJ8,"") | AX8: =IF(AND(ISNUMBER(N8),ISNUMBER(AK8)),N8+AK8,"") | ... BB8: =IF(AND(ISNUMBER(R8),ISNUMBER(AO8)),R8+AO8,"") | BC8: =IF(AND(S8="",T8=""),"",MIN(S8,T8)) -> 46291
A9: =IF(B9="","",ROW()-2) -> 7 | B9: M42993 | C9: 00191416-B - 1 - YAN KAPAK, MG SERIM | D9: =IFERROR(VALUE(TRIM(MID(C9,FIND(" - ",C9)+3,FIND(" - ",C9,FIND(" - ",C9)+3)-FIND(" - ",C9)-3))),"") -> 1 | E9: AYÇA GÖK | F9: 46288 | I9: 46288 | J9: 46290 | Q9: 46291 | T9: 46291 | Z9: =IF(B9="","",IF(S9<>"","Sevk Edildi",IF(AND(X9<>"",Y9=""),"Reworkte",IF(T9<>"","Kapandı"&IF(COUNT(G9:R9)=0,""," – "&LOOKUP(2,1/(G9:R9=MAX(G9:R9)),{"Tasarım","Ply Cutter","Üretim","Kalite (Üretim sonrası)","Talaşlı","Kalite (Talaşlı sonrası)","Montaj","Kalite (Montaj sonrası)","Boya","Kalite (Boya sonrası)","Yarı Mamül","KM"})),IF(COUNT(G9:R9)=0,"Başlamadı",LOOKUP(2,1/(G9:R9=MAX(G9:R9)),{"Tasarımda","Ply Cutter'da","Üretimde","Kalitede (Üretim sonrası)","Talaşlıda","Kalitede (Talaşlı sonrası)","Montajda","Kalitede (Montaj sonrası)","Boyada","Kalitede (Boya sonrası)","Yarı Mamülde","KM'de"})))))) -> Kapandı – Yarı Mamül | AA9: =IF(OR(B9="",F9=""),"",IFERROR(IF(S9<>"",S9-F9,IF(T9<>"",T9-F9,TODAY()-F9)),"")) -> 3 | AD9: =IF(OR($B9="",NOT(ISNUMBER(G9))),"",IF(COUNTIF(H9:$T9,G9)>0,0,IF(COUNTIF($G9:$T9,">"&G9)=0,"",SMALL($G9:$T9,COUNTIF($G9:$T9,"<="&G9)+1)-G9))) | AE9: =IF(OR($B9="",NOT(ISNUMBER(H9))),"",IF(COUNTIF(I9:$T9,H9)>0,0,IF(COUNTIF($G9:$T9,">"&H9)=0,"",SMALL($G9:$T9,COUNTIF($G9:$T9,"<="&H9)+1)-H9))) | AF9: =IF(OR($B9="",NOT(ISNUMBER(I9))),"",IF(COUNTIF(J9:$T9,I9)>0,0,IF(COUNTIF($G9:$T9,">"&I9)=0,"",SMALL($G9:$T9,COUNTIF($G9:$T9,"<="&I9)+1)-I9))) -> 2 | AG9: =IF(OR($B9="",NOT(ISNUMBER(J9))),"",IF(COUNTIF(K9:$T9,J9)>0,0,IF(COUNTIF($G9:$T9,">"&J9)=0,"",SMALL($G9:$T9,COUNTIF($G9:$T9,"<="&J9)+1)-J9))) -> 1 | AH9: =IF(OR($B9="",NOT(ISNUMBER(K9))),"",IF(COUNTIF(L9:$T9,K9)>0,0,IF(COUNTIF($G9:$T9,">"&K9)=0,"",SMALL($G9:$T9,COUNTIF($G9:$T9,"<="&K9)+1)-K9))) | AI9: =IF(OR($B9="",NOT(ISNUMBER(L9))),"",IF(COUNTIF(M9:$T9,L9)>0,0,IF(COUNTIF($G9:$T9,">"&L9)=0,"",SMALL($G9:$T9,COUNTIF($G9:$T9,"<="&L9)+1)-L9))) | AJ9: =IF(OR($B9="",NOT(ISNUMBER(M9))),"",IF(COUNTIF(N9:$T9,M9)>0,0,IF(COUNTIF($G9:$T9,">"&M9)=0,"",SMALL($G9:$T9,COUNTIF($G9:$T9,"<="&M9)+1)-M9))) | AK9: =IF(OR($B9="",NOT(ISNUMBER(N9))),"",IF(COUNTIF(O9:$T9,N9)>0,0,IF(COUNTIF($G9:$T9,">"&N9)=0,"",SMALL($G9:$T9,COUNTIF($G9:$T9,"<="&N9)+1)-N9))) | ... AO9: =IF(OR($B9="",NOT(ISNUMBER(R9))),"",IF(COUNTIF(S9:$T9,R9)>0,0,IF(COUNTIF($G9:$T9,">"&R9)=0,"",SMALL($G9:$T9,COUNTIF($G9:$T9,"<="&R9)+1)-R9))) | AP9: =IF(OR($B9="",Z9="",Z9="Başlamadı",Z9="Sevk Edildi",Z9="Reworkte",LEFT(Z9,7)="Kapandı"),0,TODAY()-MAX($G9:$R9)) -> 0 | AQ9: =IF(AND(ISNUMBER(G9),ISNUMBER(AD9)),G9+AD9,"") | AR9: =IF(AND(ISNUMBER(H9),ISNUMBER(AE9)),H9+AE9,"") | AS9: =IF(AND(ISNUMBER(I9),ISNUMBER(AF9)),I9+AF9,"") -> 46290 | AT9: =IF(AND(ISNUMBER(J9),ISNUMBER(AG9)),J9+AG9,"") -> 46291 | AU9: =IF(AND(ISNUMBER(K9),ISNUMBER(AH9)),K9+AH9,"") | AV9: =IF(AND(ISNUMBER(L9),ISNUMBER(AI9)),L9+AI9,"") | AW9: =IF(AND(ISNUMBER(M9),ISNUMBER(AJ9)),M9+AJ9,"") | AX9: =IF(AND(ISNUMBER(N9),ISNUMBER(AK9)),N9+AK9,"") | ... BB9: =IF(AND(ISNUMBER(R9),ISNUMBER(AO9)),R9+AO9,"") | BC9: =IF(AND(S9="",T9=""),"",MIN(S9,T9)) -> 46291
A10: =IF(B10="","",ROW()-2) -> 8 | B10: M42994 | C10: MN-7750-0043-B - 1 - REFLEKTOR DONER ANTEN EDELINT | D10: =IFERROR(VALUE(TRIM(MID(C10,FIND(" - ",C10)+3,FIND(" - ",C10,FIND(" - ",C10)+3)-FIND(" - ",C10)-3))),"") -> 1 | E10: AYÇA GÖK | F10: 46288 | I10: 46288 | J10: 46290 | Q10: 46291 | T10: 46291 | Z10: =IF(B10="","",IF(S10<>"","Sevk Edildi",IF(AND(X10<>"",Y10=""),"Reworkte",IF(T10<>"","Kapandı"&IF(COUNT(G10:R10)=0,""," – "&LOOKUP(2,1/(G10:R10=MAX(G10:R10)),{"Tasarım","Ply Cutter","Üretim","Kalite (Üretim sonrası)","Talaşlı","Kalite (Talaşlı sonrası)","Montaj","Kalite (Montaj sonrası)","Boya","Kalite (Boya sonrası)","Yarı Mamül","KM"})),IF(COUNT(G10:R10)=0,"Başlamadı",LOOKUP(2,1/(G10:R10=MAX(G10:R10)),{"Tasarımda","Ply Cutter'da","Üretimde","Kalitede (Üretim sonrası)","Talaşlıda","Kalitede (Talaşlı sonrası)","Montajda","Kalitede (Montaj sonrası)","Boyada","Kalitede (Boya sonrası)","Yarı Mamülde","KM'de"})))))) -> Kapandı – Yarı Mamül | AA10: =IF(OR(B10="",F10=""),"",IFERROR(IF(S10<>"",S10-F10,IF(T10<>"",T10-F10,TODAY()-F10)),"")) -> 3 | AD10: =IF(OR($B10="",NOT(ISNUMBER(G10))),"",IF(COUNTIF(H10:$T10,G10)>0,0,IF(COUNTIF($G10:$T10,">"&G10)=0,"",SMALL($G10:$T10,COUNTIF($G10:$T10,"<="&G10)+1)-G10))) | AE10: =IF(OR($B10="",NOT(ISNUMBER(H10))),"",IF(COUNTIF(I10:$T10,H10)>0,0,IF(COUNTIF($G10:$T10,">"&H10)=0,"",SMALL($G10:$T10,COUNTIF($G10:$T10,"<="&H10)+1)-H10))) | AF10: =IF(OR($B10="",NOT(ISNUMBER(I10))),"",IF(COUNTIF(J10:$T10,I10)>0,0,IF(COUNTIF($G10:$T10,">"&I10)=0,"",SMALL($G10:$T10,COUNTIF($G10:$T10,"<="&I10)+1)-I10))) -> 2 | AG10: =IF(OR($B10="",NOT(ISNUMBER(J10))),"",IF(COUNTIF(K10:$T10,J10)>0,0,IF(COUNTIF($G10:$T10,">"&J10)=0,"",SMALL($G10:$T10,COUNTIF($G10:$T10,"<="&J10)+1)-J10))) -> 1 | AH10: =IF(OR($B10="",NOT(ISNUMBER(K10))),"",IF(COUNTIF(L10:$T10,K10)>0,0,IF(COUNTIF($G10:$T10,">"&K10)=0,"",SMALL($G10:$T10,COUNTIF($G10:$T10,"<="&K10)+1)-K10))) | AI10: =IF(OR($B10="",NOT(ISNUMBER(L10))),"",IF(COUNTIF(M10:$T10,L10)>0,0,IF(COUNTIF($G10:$T10,">"&L10)=0,"",SMALL($G10:$T10,COUNTIF($G10:$T10,"<="&L10)+1)-L10))) | AJ10: =IF(OR($B10="",NOT(ISNUMBER(M10))),"",IF(COUNTIF(N10:$T10,M10)>0,0,IF(COUNTIF($G10:$T10,">"&M10)=0,"",SMALL($G10:$T10,COUNTIF($G10:$T10,"<="&M10)+1)-M10))) | AK10: =IF(OR($B10="",NOT(ISNUMBER(N10))),"",IF(COUNTIF(O10:$T10,N10)>0,0,IF(COUNTIF($G10:$T10,">"&N10)=0,"",SMALL($G10:$T10,COUNTIF($G10:$T10,"<="&N10)+1)-N10))) | ... AO10: =IF(OR($B10="",NOT(ISNUMBER(R10))),"",IF(COUNTIF(S10:$T10,R10)>0,0,IF(COUNTIF($G10:$T10,">"&R10)=0,"",SMALL($G10:$T10,COUNTIF($G10:$T10,"<="&R10)+1)-R10))) | AP10: =IF(OR($B10="",Z10="",Z10="Başlamadı",Z10="Sevk Edildi",Z10="Reworkte",LEFT(Z10,7)="Kapandı"),0,TODAY()-MAX($G10:$R10)) -> 0 | AQ10: =IF(AND(ISNUMBER(G10),ISNUMBER(AD10)),G10+AD10,"") | AR10: =IF(AND(ISNUMBER(H10),ISNUMBER(AE10)),H10+AE10,"") | AS10: =IF(AND(ISNUMBER(I10),ISNUMBER(AF10)),I10+AF10,"") -> 46290 | AT10: =IF(AND(ISNUMBER(J10),ISNUMBER(AG10)),J10+AG10,"") -> 46291 | AU10: =IF(AND(ISNUMBER(K10),ISNUMBER(AH10)),K10+AH10,"") | AV10: =IF(AND(ISNUMBER(L10),ISNUMBER(AI10)),L10+AI10,"") | AW10: =IF(AND(ISNUMBER(M10),ISNUMBER(AJ10)),M10+AJ10,"") | AX10: =IF(AND(ISNUMBER(N10),ISNUMBER(AK10)),N10+AK10,"") | ... BB10: =IF(AND(ISNUMBER(R10),ISNUMBER(AO10)),R10+AO10,"") | BC10: =IF(AND(S10="",T10=""),"",MIN(S10,T10)) -> 46291
A11: =IF(B11="","",ROW()-2) -> 9 | B11: M42995 | C11: MN-7637-0011-B - 1 - RADOM KOMPOZIT BANT 7 SERIM | D11: =IFERROR(VALUE(TRIM(MID(C11,FIND(" - ",C11)+3,FIND(" - ",C11,FIND(" - ",C11)+3)-FIND(" - ",C11)-3))),"") -> 1 | E11: AYÇA GÖK | F11: 46288 | I11: 46289 | J11: 46290 | Q11: 46291 | T11: 46291 | Z11: =IF(B11="","",IF(S11<>"","Sevk Edildi",IF(AND(X11<>"",Y11=""),"Reworkte",IF(T11<>"","Kapandı"&IF(COUNT(G11:R11)=0,""," – "&LOOKUP(2,1/(G11:R11=MAX(G11:R11)),{"Tasarım","Ply Cutter","Üretim","Kalite (Üretim sonrası)","Talaşlı","Kalite (Talaşlı sonrası)","Montaj","Kalite (Montaj sonrası)","Boya","Kalite (Boya sonrası)","Yarı Mamül","KM"})),IF(COUNT(G11:R11)=0,"Başlamadı",LOOKUP(2,1/(G11:R11=MAX(G11:R11)),{"Tasarımda","Ply Cutter'da","Üretimde","Kalitede (Üretim sonrası)","Talaşlıda","Kalitede (Talaşlı sonrası)","Montajda","Kalitede (Montaj sonrası)","Boyada","Kalitede (Boya sonrası)","Yarı Mamülde","KM'de"})))))) -> Kapandı – Yarı Mamül | AA11: =IF(OR(B11="",F11=""),"",IFERROR(IF(S11<>"",S11-F11,IF(T11<>"",T11-F11,TODAY()-F11)),"")) -> 3 | AD11: =IF(OR($B11="",NOT(ISNUMBER(G11))),"",IF(COUNTIF(H11:$T11,G11)>0,0,IF(COUNTIF($G11:$T11,">"&G11)=0,"",SMALL($G11:$T11,COUNTIF($G11:$T11,"<="&G11)+1)-G11))) | AE11: =IF(OR($B11="",NOT(ISNUMBER(H11))),"",IF(COUNTIF(I11:$T11,H11)>0,0,IF(COUNTIF($G11:$T11,">"&H11)=0,"",SMALL($G11:$T11,COUNTIF($G11:$T11,"<="&H11)+1)-H11))) | AF11: =IF(OR($B11="",NOT(ISNUMBER(I11))),"",IF(COUNTIF(J11:$T11,I11)>0,0,IF(COUNTIF($G11:$T11,">"&I11)=0,"",SMALL($G11:$T11,COUNTIF($G11:$T11,"<="&I11)+1)-I11))) -> 1 | AG11: =IF(OR($B11="",NOT(ISNUMBER(J11))),"",IF(COUNTIF(K11:$T11,J11)>0,0,IF(COUNTIF($G11:$T11,">"&J11)=0,"",SMALL($G11:$T11,COUNTIF($G11:$T11,"<="&J11)+1)-J11))) -> 1 | AH11: =IF(OR($B11="",NOT(ISNUMBER(K11))),"",IF(COUNTIF(L11:$T11,K11)>0,0,IF(COUNTIF($G11:$T11,">"&K11)=0,"",SMALL($G11:$T11,COUNTIF($G11:$T11,"<="&K11)+1)-K11))) | AI11: =IF(OR($B11="",NOT(ISNUMBER(L11))),"",IF(COUNTIF(M11:$T11,L11)>0,0,IF(COUNTIF($G11:$T11,">"&L11)=0,"",SMALL($G11:$T11,COUNTIF($G11:$T11,"<="&L11)+1)-L11))) | AJ11: =IF(OR($B11="",NOT(ISNUMBER(M11))),"",IF(COUNTIF(N11:$T11,M11)>0,0,IF(COUNTIF($G11:$T11,">"&M11)=0,"",SMALL($G11:$T11,COUNTIF($G11:$T11,"<="&M11)+1)-M11))) | AK11: =IF(OR($B11="",NOT(ISNUMBER(N11))),"",IF(COUNTIF(O11:$T11,N11)>0,0,IF(COUNTIF($G11:$T11,">"&N11)=0,"",SMALL($G11:$T11,COUNTIF($G11:$T11,"<="&N11)+1)-N11))) | ... AO11: =IF(OR($B11="",NOT(ISNUMBER(R11))),"",IF(COUNTIF(S11:$T11,R11)>0,0,IF(COUNTIF($G11:$T11,">"&R11)=0,"",SMALL($G11:$T11,COUNTIF($G11:$T11,"<="&R11)+1)-R11))) | AP11: =IF(OR($B11="",Z11="",Z11="Başlamadı",Z11="Sevk Edildi",Z11="Reworkte",LEFT(Z11,7)="Kapandı"),0,TODAY()-MAX($G11:$R11)) -> 0 | AQ11: =IF(AND(ISNUMBER(G11),ISNUMBER(AD11)),G11+AD11,"") | AR11: =IF(AND(ISNUMBER(H11),ISNUMBER(AE11)),H11+AE11,"") | AS11: =IF(AND(ISNUMBER(I11),ISNUMBER(AF11)),I11+AF11,"") -> 46290 | AT11: =IF(AND(ISNUMBER(J11),ISNUMBER(AG11)),J11+AG11,"") -> 46291 | AU11: =IF(AND(ISNUMBER(K11),ISNUMBER(AH11)),K11+AH11,"") | AV11: =IF(AND(ISNUMBER(L11),ISNUMBER(AI11)),L11+AI11,"") | AW11: =IF(AND(ISNUMBER(M11),ISNUMBER(AJ11)),M11+AJ11,"") | AX11: =IF(AND(ISNUMBER(N11),ISNUMBER(AK11)),N11+AK11,"") | ... BB11: =IF(AND(ISNUMBER(R11),ISNUMBER(AO11)),R11+AO11,"") | BC11: =IF(AND(S11="",T11=""),"",MIN(S11,T11)) -> 46291
A12: =IF(B12="","",ROW()-2) -> 10 | B12: M42985 | C12: SOM0007-B - 1 - SOM-SAG KANAT LAY UP | D12: =IFERROR(VALUE(TRIM(MID(C12,FIND(" - ",C12)+3,FIND(" - ",C12,FIND(" - ",C12)+3)-FIND(" - ",C12)-3))),"") -> 1 | E12: AYÇA GÖK | F12: 46288 | I12: 46288 | J12: 46290 | T12: 46290 | Z12: =IF(B12="","",IF(S12<>"","Sevk Edildi",IF(AND(X12<>"",Y12=""),"Reworkte",IF(T12<>"","Kapandı"&IF(COUNT(G12:R12)=0,""," – "&LOOKUP(2,1/(G12:R12=MAX(G12:R12)),{"Tasarım","Ply Cutter","Üretim","Kalite (Üretim sonrası)","Talaşlı","Kalite (Talaşlı sonrası)","Montaj","Kalite (Montaj sonrası)","Boya","Kalite (Boya sonrası)","Yarı Mamül","KM"})),IF(COUNT(G12:R12)=0,"Başlamadı",LOOKUP(2,1/(G12:R12=MAX(G12:R12)),{"Tasarımda","Ply Cutter'da","Üretimde","Kalitede (Üretim sonrası)","Talaşlıda","Kalitede (Talaşlı sonrası)","Montajda","Kalitede (Montaj sonrası)","Boyada","Kalitede (Boya sonrası)","Yarı Mamülde","KM'de"})))))) -> Kapandı – Kalite (Üretim sonrası) | AA12: =IF(OR(B12="",F12=""),"",IFERROR(IF(S12<>"",S12-F12,IF(T12<>"",T12-F12,TODAY()-F12)),"")) -> 2 | AD12: =IF(OR($B12="",NOT(ISNUMBER(G12))),"",IF(COUNTIF(H12:$T12,G12)>0,0,IF(COUNTIF($G12:$T12,">"&G12)=0,"",SMALL($G12:$T12,COUNTIF($G12:$T12,"<="&G12)+1)-G12))) | AE12: =IF(OR($B12="",NOT(ISNUMBER(H12))),"",IF(COUNTIF(I12:$T12,H12)>0,0,IF(COUNTIF($G12:$T12,">"&H12)=0,"",SMALL($G12:$T12,COUNTIF($G12:$T12,"<="&H12)+1)-H12))) | AF12: =IF(OR($B12="",NOT(ISNUMBER(I12))),"",IF(COUNTIF(J12:$T12,I12)>0,0,IF(COUNTIF($G12:$T12,">"&I12)=0,"",SMALL($G12:$T12,COUNTIF($G12:$T12,"<="&I12)+1)-I12))) -> 2 | AG12: =IF(OR($B12="",NOT(ISNUMBER(J12))),"",IF(COUNTIF(K12:$T12,J12)>0,0,IF(COUNTIF($G12:$T12,">"&J12)=0,"",SMALL($G12:$T12,COUNTIF($G12:$T12,"<="&J12)+1)-J12))) -> 0 | AH12: =IF(OR($B12="",NOT(ISNUMBER(K12))),"",IF(COUNTIF(L12:$T12,K12)>0,0,IF(COUNTIF($G12:$T12,">"&K12)=0,"",SMALL($G12:$T12,COUNTIF($G12:$T12,"<="&K12)+1)-K12))) | AI12: =IF(OR($B12="",NOT(ISNUMBER(L12))),"",IF(COUNTIF(M12:$T12,L12)>0,0,IF(COUNTIF($G12:$T12,">"&L12)=0,"",SMALL($G12:$T12,COUNTIF($G12:$T12,"<="&L12)+1)-L12))) | AJ12: =IF(OR($B12="",NOT(ISNUMBER(M12))),"",IF(COUNTIF(N12:$T12,M12)>0,0,IF(COUNTIF($G12:$T12,">"&M12)=0,"",SMALL($G12:$T12,COUNTIF($G12:$T12,"<="&M12)+1)-M12))) | AK12: =IF(OR($B12="",NOT(ISNUMBER(N12))),"",IF(COUNTIF(O12:$T12,N12)>0,0,IF(COUNTIF($G12:$T12,">"&N12)=0,"",SMALL($G12:$T12,COUNTIF($G12:$T12,"<="&N12)+1)-N12))) | ... AO12: =IF(OR($B12="",NOT(ISNUMBER(R12))),"",IF(COUNTIF(S12:$T12,R12)>0,0,IF(COUNTIF($G12:$T12,">"&R12)=0,"",SMALL($G12:$T12,COUNTIF($G12:$T12,"<="&R12)+1)-R12))) | AP12: =IF(OR($B12="",Z12="",Z12="Başlamadı",Z12="Sevk Edildi",Z12="Reworkte",LEFT(Z12,7)="Kapandı"),0,TODAY()-MAX($G12:$R12)) -> 0 | AQ12: =IF(AND(ISNUMBER(G12),ISNUMBER(AD12)),G12+AD12,"") | AR12: =IF(AND(ISNUMBER(H12),ISNUMBER(AE12)),H12+AE12,"") | AS12: =IF(AND(ISNUMBER(I12),ISNUMBER(AF12)),I12+AF12,"") -> 46290 | AT12: =IF(AND(ISNUMBER(J12),ISNUMBER(AG12)),J12+AG12,"") -> 46290 | AU12: =IF(AND(ISNUMBER(K12),ISNUMBER(AH12)),K12+AH12,"") | AV12: =IF(AND(ISNUMBER(L12),ISNUMBER(AI12)),L12+AI12,"") | AW12: =IF(AND(ISNUMBER(M12),ISNUMBER(AJ12)),M12+AJ12,"") | AX12: =IF(AND(ISNUMBER(N12),ISNUMBER(AK12)),N12+AK12,"") | ... BB12: =IF(AND(ISNUMBER(R12),ISNUMBER(AO12)),R12+AO12,"") | BC12: =IF(AND(S12="",T12=""),"",MIN(S12,T12)) -> 46290
A13: =IF(B13="","",ROW()-2) -> 11 | B13: M42996 | C13: 00190331-B - 1 - HAVA ALIGI KAPAGI SERIM | D13: =IFERROR(VALUE(TRIM(MID(C13,FIND(" - ",C13)+3,FIND(" - ",C13,FIND(" - ",C13)+3)-FIND(" - ",C13)-3))),"") -> 1 | E13: AYÇA GÖK | F13: 46288 | I13: 46288 | J13: 46290 | Q13: 46296 | T13: 46296 | Z13: =IF(B13="","",IF(S13<>"","Sevk Edildi",IF(AND(X13<>"",Y13=""),"Reworkte",IF(T13<>"","Kapandı"&IF(COUNT(G13:R13)=0,""," – "&LOOKUP(2,1/(G13:R13=MAX(G13:R13)),{"Tasarım","Ply Cutter","Üretim","Kalite (Üretim sonrası)","Talaşlı","Kalite (Talaşlı sonrası)","Montaj","Kalite (Montaj sonrası)","Boya","Kalite (Boya sonrası)","Yarı Mamül","KM"})),IF(COUNT(G13:R13)=0,"Başlamadı",LOOKUP(2,1/(G13:R13=MAX(G13:R13)),{"Tasarımda","Ply Cutter'da","Üretimde","Kalitede (Üretim sonrası)","Talaşlıda","Kalitede (Talaşlı sonrası)","Montajda","Kalitede (Montaj sonrası)","Boyada","Kalitede (Boya sonrası)","Yarı Mamülde","KM'de"})))))) -> Kapandı – Yarı Mamül | AA13: =IF(OR(B13="",F13=""),"",IFERROR(IF(S13<>"",S13-F13,IF(T13<>"",T13-F13,TODAY()-F13)),"")) -> 8 | AD13: =IF(OR($B13="",NOT(ISNUMBER(G13))),"",IF(COUNTIF(H13:$T13,G13)>0,0,IF(COUNTIF($G13:$T13,">"&G13)=0,"",SMALL($G13:$T13,COUNTIF($G13:$T13,"<="&G13)+1)-G13))) | AE13: =IF(OR($B13="",NOT(ISNUMBER(H13))),"",IF(COUNTIF(I13:$T13,H13)>0,0,IF(COUNTIF($G13:$T13,">"&H13)=0,"",SMALL($G13:$T13,COUNTIF($G13:$T13,"<="&H13)+1)-H13))) | AF13: =IF(OR($B13="",NOT(ISNUMBER(I13))),"",IF(COUNTIF(J13:$T13,I13)>0,0,IF(COUNTIF($G13:$T13,">"&I13)=0,"",SMALL($G13:$T13,COUNTIF($G13:$T13,"<="&I13)+1)-I13))) -> 2 | AG13: =IF(OR($B13="",NOT(ISNUMBER(J13))),"",IF(COUNTIF(K13:$T13,J13)>0,0,IF(COUNTIF($G13:$T13,">"&J13)=0,"",SMALL($G13:$T13,COUNTIF($G13:$T13,"<="&J13)+1)-J13))) -> 6 | AH13: =IF(OR($B13="",NOT(ISNUMBER(K13))),"",IF(COUNTIF(L13:$T13,K13)>0,0,IF(COUNTIF($G13:$T13,">"&K13)=0,"",SMALL($G13:$T13,COUNTIF($G13:$T13,"<="&K13)+1)-K13))) | AI13: =IF(OR($B13="",NOT(ISNUMBER(L13))),"",IF(COUNTIF(M13:$T13,L13)>0,0,IF(COUNTIF($G13:$T13,">"&L13)=0,"",SMALL($G13:$T13,COUNTIF($G13:$T13,"<="&L13)+1)-L13))) | AJ13: =IF(OR($B13="",NOT(ISNUMBER(M13))),"",IF(COUNTIF(N13:$T13,M13)>0,0,IF(COUNTIF($G13:$T13,">"&M13)=0,"",SMALL($G13:$T13,COUNTIF($G13:$T13,"<="&M13)+1)-M13))) | AK13: =IF(OR($B13="",NOT(ISNUMBER(N13))),"",IF(COUNTIF(O13:$T13,N13)>0,0,IF(COUNTIF($G13:$T13,">"&N13)=0,"",SMALL($G13:$T13,COUNTIF($G13:$T13,"<="&N13)+1)-N13))) | ... AO13: =IF(OR($B13="",NOT(ISNUMBER(R13))),"",IF(COUNTIF(S13:$T13,R13)>0,0,IF(COUNTIF($G13:$T13,">"&R13)=0,"",SMALL($G13:$T13,COUNTIF($G13:$T13,"<="&R13)+1)-R13))) | AP13: =IF(OR($B13="",Z13="",Z13="Başlamadı",Z13="Sevk Edildi",Z13="Reworkte",LEFT(Z13,7)="Kapandı"),0,TODAY()-MAX($G13:$R13)) -> 0 | AQ13: =IF(AND(ISNUMBER(G13),ISNUMBER(AD13)),G13+AD13,"") | AR13: =IF(AND(ISNUMBER(H13),ISNUMBER(AE13)),H13+AE13,"") | AS13: =IF(AND(ISNUMBER(I13),ISNUMBER(AF13)),I13+AF13,"") -> 46290 | AT13: =IF(AND(ISNUMBER(J13),ISNUMBER(AG13)),J13+AG13,"") -> 46296 | AU13: =IF(AND(ISNUMBER(K13),ISNUMBER(AH13)),K13+AH13,"") | AV13: =IF(AND(ISNUMBER(L13),ISNUMBER(AI13)),L13+AI13,"") | AW13: =IF(AND(ISNUMBER(M13),ISNUMBER(AJ13)),M13+AJ13,"") | AX13: =IF(AND(ISNUMBER(N13),ISNUMBER(AK13)),N13+AK13,"") | ... BB13: =IF(AND(ISNUMBER(R13),ISNUMBER(AO13)),R13+AO13,"") | BC13: =IF(AND(S13="",T13=""),"",MIN(S13,T13)) -> 46296
A14: =IF(B14="","",ROW()-2) -> 12 | B14: M42997 | C14: SOM0007-D - 1 - SOM SAG KANAT MONTAJ | D14: =IFERROR(VALUE(TRIM(MID(C14,FIND(" - ",C14)+3,FIND(" - ",C14,FIND(" - ",C14)+3)-FIND(" - ",C14)-3))),"") -> 1 | E14: AYÇA GÖK | F14: 46288 | M14: 46288 | N14: 46291 | T14: 46291 | Z14: =IF(B14="","",IF(S14<>"","Sevk Edildi",IF(AND(X14<>"",Y14=""),"Reworkte",IF(T14<>"","Kapandı"&IF(COUNT(G14:R14)=0,""," – "&LOOKUP(2,1/(G14:R14=MAX(G14:R14)),{"Tasarım","Ply Cutter","Üretim","Kalite (Üretim sonrası)","Talaşlı","Kalite (Talaşlı sonrası)","Montaj","Kalite (Montaj sonrası)","Boya","Kalite (Boya sonrası)","Yarı Mamül","KM"})),IF(COUNT(G14:R14)=0,"Başlamadı",LOOKUP(2,1/(G14:R14=MAX(G14:R14)),{"Tasarımda","Ply Cutter'da","Üretimde","Kalitede (Üretim sonrası)","Talaşlıda","Kalitede (Talaşlı sonrası)","Montajda","Kalitede (Montaj sonrası)","Boyada","Kalitede (Boya sonrası)","Yarı Mamülde","KM'de"})))))) -> Kapandı – Kalite (Montaj sonrası) | AA14: =IF(OR(B14="",F14=""),"",IFERROR(IF(S14<>"",S14-F14,IF(T14<>"",T14-F14,TODAY()-F14)),"")) -> 3 | AD14: =IF(OR($B14="",NOT(ISNUMBER(G14))),"",IF(COUNTIF(H14:$T14,G14)>0,0,IF(COUNTIF($G14:$T14,">"&G14)=0,"",SMALL($G14:$T14,COUNTIF($G14:$T14,"<="&G14)+1)-G14))) | AE14: =IF(OR($B14="",NOT(ISNUMBER(H14))),"",IF(COUNTIF(I14:$T14,H14)>0,0,IF(COUNTIF($G14:$T14,">"&H14)=0,"",SMALL($G14:$T14,COUNTIF($G14:$T14,"<="&H14)+1)-H14))) | AF14: =IF(OR($B14="",NOT(ISNUMBER(I14))),"",IF(COUNTIF(J14:$T14,I14)>0,0,IF(COUNTIF($G14:$T14,">"&I14)=0,"",SMALL($G14:$T14,COUNTIF($G14:$T14,"<="&I14)+1)-I14))) | AG14: =IF(OR($B14="",NOT(ISNUMBER(J14))),"",IF(COUNTIF(K14:$T14,J14)>0,0,IF(COUNTIF($G14:$T14,">"&J14)=0,"",SMALL($G14:$T14,COUNTIF($G14:$T14,"<="&J14)+1)-J14))) | AH14: =IF(OR($B14="",NOT(ISNUMBER(K14))),"",IF(COUNTIF(L14:$T14,K14)>0,0,IF(COUNTIF($G14:$T14,">"&K14)=0,"",SMALL($G14:$T14,COUNTIF($G14:$T14,"<="&K14)+1)-K14))) | AI14: =IF(OR($B14="",NOT(ISNUMBER(L14))),"",IF(COUNTIF(M14:$T14,L14)>0,0,IF(COUNTIF($G14:$T14,">"&L14)=0,"",SMALL($G14:$T14,COUNTIF($G14:$T14,"<="&L14)+1)-L14))) | AJ14: =IF(OR($B14="",NOT(ISNUMBER(M14))),"",IF(COUNTIF(N14:$T14,M14)>0,0,IF(COUNTIF($G14:$T14,">"&M14)=0,"",SMALL($G14:$T14,COUNTIF($G14:$T14,"<="&M14)+1)-M14))) -> 3 | AK14: =IF(OR($B14="",NOT(ISNUMBER(N14))),"",IF(COUNTIF(O14:$T14,N14)>0,0,IF(COUNTIF($G14:$T14,">"&N14)=0,"",SMALL($G14:$T14,COUNTIF($G14:$T14,"<="&N14)+1)-N14))) -> 0 | ... AO14: =IF(OR($B14="",NOT(ISNUMBER(R14))),"",IF(COUNTIF(S14:$T14,R14)>0,0,IF(COUNTIF($G14:$T14,">"&R14)=0,"",SMALL($G14:$T14,COUNTIF($G14:$T14,"<="&R14)+1)-R14))) | AP14: =IF(OR($B14="",Z14="",Z14="Başlamadı",Z14="Sevk Edildi",Z14="Reworkte",LEFT(Z14,7)="Kapandı"),0,TODAY()-MAX($G14:$R14)) -> 0 | AQ14: =IF(AND(ISNUMBER(G14),ISNUMBER(AD14)),G14+AD14,"") | AR14: =IF(AND(ISNUMBER(H14),ISNUMBER(AE14)),H14+AE14,"") | AS14: =IF(AND(ISNUMBER(I14),ISNUMBER(AF14)),I14+AF14,"") | AT14: =IF(AND(ISNUMBER(J14),ISNUMBER(AG14)),J14+AG14,"") | AU14: =IF(AND(ISNUMBER(K14),ISNUMBER(AH14)),K14+AH14,"") | AV14: =IF(AND(ISNUMBER(L14),ISNUMBER(AI14)),L14+AI14,"") | AW14: =IF(AND(ISNUMBER(M14),ISNUMBER(AJ14)),M14+AJ14,"") -> 46291 | AX14: =IF(AND(ISNUMBER(N14),ISNUMBER(AK14)),N14+AK14,"") -> 46291 | ... BB14: =IF(AND(ISNUMBER(R14),ISNUMBER(AO14)),R14+AO14,"") | BC14: =IF(AND(S14="",T14=""),"",MIN(S14,T14)) -> 46291
A15: =IF(B15="","",ROW()-2) -> 13 | B15: M42998 | C15: SOM0010-D - 1 - SOM SOL KANAT MONTAJ | D15: =IFERROR(VALUE(TRIM(MID(C15,FIND(" - ",C15)+3,FIND(" - ",C15,FIND(" - ",C15)+3)-FIND(" - ",C15)-3))),"") -> 1 | E15: AYÇA GÖK | F15: 46288 | M15: 46288 | N15: 46291 | T15: 46291 | Z15: =IF(B15="","",IF(S15<>"","Sevk Edildi",IF(AND(X15<>"",Y15=""),"Reworkte",IF(T15<>"","Kapandı"&IF(COUNT(G15:R15)=0,""," – "&LOOKUP(2,1/(G15:R15=MAX(G15:R15)),{"Tasarım","Ply Cutter","Üretim","Kalite (Üretim sonrası)","Talaşlı","Kalite (Talaşlı sonrası)","Montaj","Kalite (Montaj sonrası)","Boya","Kalite (Boya sonrası)","Yarı Mamül","KM"})),IF(COUNT(G15:R15)=0,"Başlamadı",LOOKUP(2,1/(G15:R15=MAX(G15:R15)),{"Tasarımda","Ply Cutter'da","Üretimde","Kalitede (Üretim sonrası)","Talaşlıda","Kalitede (Talaşlı sonrası)","Montajda","Kalitede (Montaj sonrası)","Boyada","Kalitede (Boya sonrası)","Yarı Mamülde","KM'de"})))))) -> Kapandı – Kalite (Montaj sonrası) | AA15: =IF(OR(B15="",F15=""),"",IFERROR(IF(S15<>"",S15-F15,IF(T15<>"",T15-F15,TODAY()-F15)),"")) -> 3 | AD15: =IF(OR($B15="",NOT(ISNUMBER(G15))),"",IF(COUNTIF(H15:$T15,G15)>0,0,IF(COUNTIF($G15:$T15,">"&G15)=0,"",SMALL($G15:$T15,COUNTIF($G15:$T15,"<="&G15)+1)-G15))) | AE15: =IF(OR($B15="",NOT(ISNUMBER(H15))),"",IF(COUNTIF(I15:$T15,H15)>0,0,IF(COUNTIF($G15:$T15,">"&H15)=0,"",SMALL($G15:$T15,COUNTIF($G15:$T15,"<="&H15)+1)-H15))) | AF15: =IF(OR($B15="",NOT(ISNUMBER(I15))),"",IF(COUNTIF(J15:$T15,I15)>0,0,IF(COUNTIF($G15:$T15,">"&I15)=0,"",SMALL($G15:$T15,COUNTIF($G15:$T15,"<="&I15)+1)-I15))) | AG15: =IF(OR($B15="",NOT(ISNUMBER(J15))),"",IF(COUNTIF(K15:$T15,J15)>0,0,IF(COUNTIF($G15:$T15,">"&J15)=0,"",SMALL($G15:$T15,COUNTIF($G15:$T15,"<="&J15)+1)-J15))) | AH15: =IF(OR($B15="",NOT(ISNUMBER(K15))),"",IF(COUNTIF(L15:$T15,K15)>0,0,IF(COUNTIF($G15:$T15,">"&K15)=0,"",SMALL($G15:$T15,COUNTIF($G15:$T15,"<="&K15)+1)-K15))) | AI15: =IF(OR($B15="",NOT(ISNUMBER(L15))),"",IF(COUNTIF(M15:$T15,L15)>0,0,IF(COUNTIF($G15:$T15,">"&L15)=0,"",SMALL($G15:$T15,COUNTIF($G15:$T15,"<="&L15)+1)-L15))) | AJ15: =IF(OR($B15="",NOT(ISNUMBER(M15))),"",IF(COUNTIF(N15:$T15,M15)>0,0,IF(COUNTIF($G15:$T15,">"&M15)=0,"",SMALL($G15:$T15,COUNTIF($G15:$T15,"<="&M15)+1)-M15))) -> 3 | AK15: =IF(OR($B15="",NOT(ISNUMBER(N15))),"",IF(COUNTIF(O15:$T15,N15)>0,0,IF(COUNTIF($G15:$T15,">"&N15)=0,"",SMALL($G15:$T15,COUNTIF($G15:$T15,"<="&N15)+1)-N15))) -> 0 | ... AO15: =IF(OR($B15="",NOT(ISNUMBER(R15))),"",IF(COUNTIF(S15:$T15,R15)>0,0,IF(COUNTIF($G15:$T15,">"&R15)=0,"",SMALL($G15:$T15,COUNTIF($G15:$T15,"<="&R15)+1)-R15))) | AP15: =IF(OR($B15="",Z15="",Z15="Başlamadı",Z15="Sevk Edildi",Z15="Reworkte",LEFT(Z15,7)="Kapandı"),0,TODAY()-MAX($G15:$R15)) -> 0 | AQ15: =IF(AND(ISNUMBER(G15),ISNUMBER(AD15)),G15+AD15,"") | AR15: =IF(AND(ISNUMBER(H15),ISNUMBER(AE15)),H15+AE15,"") | AS15: =IF(AND(ISNUMBER(I15),ISNUMBER(AF15)),I15+AF15,"") | AT15: =IF(AND(ISNUMBER(J15),ISNUMBER(AG15)),J15+AG15,"") | AU15: =IF(AND(ISNUMBER(K15),ISNUMBER(AH15)),K15+AH15,"") | AV15: =IF(AND(ISNUMBER(L15),ISNUMBER(AI15)),L15+AI15,"") | AW15: =IF(AND(ISNUMBER(M15),ISNUMBER(AJ15)),M15+AJ15,"") -> 46291 | AX15: =IF(AND(ISNUMBER(N15),ISNUMBER(AK15)),N15+AK15,"") -> 46291 | ... BB15: =IF(AND(ISNUMBER(R15),ISNUMBER(AO15)),R15+AO15,"") | BC15: =IF(AND(S15="",T15=""),"",MIN(S15,T15)) -> 46291
A16: =IF(B16="","",ROW()-2) -> 14 | B16: M42999 | C16: 00043946-B - 1 - RAMPA-HA -LAY UP | D16: =IFERROR(VALUE(TRIM(MID(C16,FIND(" - ",C16)+3,FIND(" - ",C16,FIND(" - ",C16)+3)-FIND(" - ",C16)-3))),"") -> 1 | E16: AYÇA GÖK | F16: 46288 | I16: 46288 | J16: 46290 | Q16: 46291 | T16: 46291 | Z16: =IF(B16="","",IF(S16<>"","Sevk Edildi",IF(AND(X16<>"",Y16=""),"Reworkte",IF(T16<>"","Kapandı"&IF(COUNT(G16:R16)=0,""," – "&LOOKUP(2,1/(G16:R16=MAX(G16:R16)),{"Tasarım","Ply Cutter","Üretim","Kalite (Üretim sonrası)","Talaşlı","Kalite (Talaşlı sonrası)","Montaj","Kalite (Montaj sonrası)","Boya","Kalite (Boya sonrası)","Yarı Mamül","KM"})),IF(COUNT(G16:R16)=0,"Başlamadı",LOOKUP(2,1/(G16:R16=MAX(G16:R16)),{"Tasarımda","Ply Cutter'da","Üretimde","Kalitede (Üretim sonrası)","Talaşlıda","Kalitede (Talaşlı sonrası)","Montajda","Kalitede (Montaj sonrası)","Boyada","Kalitede (Boya sonrası)","Yarı Mamülde","KM'de"})))))) -> Kapandı – Yarı Mamül | AA16: =IF(OR(B16="",F16=""),"",IFERROR(IF(S16<>"",S16-F16,IF(T16<>"",T16-F16,TODAY()-F16)),"")) -> 3 | AD16: =IF(OR($B16="",NOT(ISNUMBER(G16))),"",IF(COUNTIF(H16:$T16,G16)>0,0,IF(COUNTIF($G16:$T16,">"&G16)=0,"",SMALL($G16:$T16,COUNTIF($G16:$T16,"<="&G16)+1)-G16))) | AE16: =IF(OR($B16="",NOT(ISNUMBER(H16))),"",IF(COUNTIF(I16:$T16,H16)>0,0,IF(COUNTIF($G16:$T16,">"&H16)=0,"",SMALL($G16:$T16,COUNTIF($G16:$T16,"<="&H16)+1)-H16))) | AF16: =IF(OR($B16="",NOT(ISNUMBER(I16))),"",IF(COUNTIF(J16:$T16,I16)>0,0,IF(COUNTIF($G16:$T16,">"&I16)=0,"",SMALL($G16:$T16,COUNTIF($G16:$T16,"<="&I16)+1)-I16))) -> 2 | AG16: =IF(OR($B16="",NOT(ISNUMBER(J16))),"",IF(COUNTIF(K16:$T16,J16)>0,0,IF(COUNTIF($G16:$T16,">"&J16)=0,"",SMALL($G16:$T16,COUNTIF($G16:$T16,"<="&J16)+1)-J16))) -> 1 | AH16: =IF(OR($B16="",NOT(ISNUMBER(K16))),"",IF(COUNTIF(L16:$T16,K16)>0,0,IF(COUNTIF($G16:$T16,">"&K16)=0,"",SMALL($G16:$T16,COUNTIF($G16:$T16,"<="&K16)+1)-K16))) | AI16: =IF(OR($B16="",NOT(ISNUMBER(L16))),"",IF(COUNTIF(M16:$T16,L16)>0,0,IF(COUNTIF($G16:$T16,">"&L16)=0,"",SMALL($G16:$T16,COUNTIF($G16:$T16,"<="&L16)+1)-L16))) | AJ16: =IF(OR($B16="",NOT(ISNUMBER(M16))),"",IF(COUNTIF(N16:$T16,M16)>0,0,IF(COUNTIF($G16:$T16,">"&M16)=0,"",SMALL($G16:$T16,COUNTIF($G16:$T16,"<="&M16)+1)-M16))) | AK16: =IF(OR($B16="",NOT(ISNUMBER(N16))),"",IF(COUNTIF(O16:$T16,N16)>0,0,IF(COUNTIF($G16:$T16,">"&N16)=0,"",SMALL($G16:$T16,COUNTIF($G16:$T16,"<="&N16)+1)-N16))) | ... AO16: =IF(OR($B16="",NOT(ISNUMBER(R16))),"",IF(COUNTIF(S16:$T16,R16)>0,0,IF(COUNTIF($G16:$T16,">"&R16)=0,"",SMALL($G16:$T16,COUNTIF($G16:$T16,"<="&R16)+1)-R16))) | AP16: =IF(OR($B16="",Z16="",Z16="Başlamadı",Z16="Sevk Edildi",Z16="Reworkte",LEFT(Z16,7)="Kapandı"),0,TODAY()-MAX($G16:$R16)) -> 0 | AQ16: =IF(AND(ISNUMBER(G16),ISNUMBER(AD16)),G16+AD16,"") | AR16: =IF(AND(ISNUMBER(H16),ISNUMBER(AE16)),H16+AE16,"") | AS16: =IF(AND(ISNUMBER(I16),ISNUMBER(AF16)),I16+AF16,"") -> 46290 | AT16: =IF(AND(ISNUMBER(J16),ISNUMBER(AG16)),J16+AG16,"") -> 46291 | AU16: =IF(AND(ISNUMBER(K16),ISNUMBER(AH16)),K16+AH16,"") | AV16: =IF(AND(ISNUMBER(L16),ISNUMBER(AI16)),L16+AI16,"") | AW16: =IF(AND(ISNUMBER(M16),ISNUMBER(AJ16)),M16+AJ16,"") | AX16: =IF(AND(ISNUMBER(N16),ISNUMBER(AK16)),N16+AK16,"") | ... BB16: =IF(AND(ISNUMBER(R16),ISNUMBER(AO16)),R16+AO16,"") | BC16: =IF(AND(S16="",T16=""),"",MIN(S16,T16)) -> 46291
A17: =IF(B17="","",ROW()-2) -> 15 | B17: M43000 | C17: 00043948-B - 1 - KAPORTA-HA LAY UP | D17: =IFERROR(VALUE(TRIM(MID(C17,FIND(" - ",C17)+3,FIND(" - ",C17,FIND(" - ",C17)+3)-FIND(" - ",C17)-3))),"") -> 1 | E17: AYÇA GÖK | F17: 46288 | I17: 46288 | J17: 46290 | Q17: 46291 | T17: 46291 | Z17: =IF(B17="","",IF(S17<>"","Sevk Edildi",IF(AND(X17<>"",Y17=""),"Reworkte",IF(T17<>"","Kapandı"&IF(COUNT(G17:R17)=0,""," – "&LOOKUP(2,1/(G17:R17=MAX(G17:R17)),{"Tasarım","Ply Cutter","Üretim","Kalite (Üretim sonrası)","Talaşlı","Kalite (Talaşlı sonrası)","Montaj","Kalite (Montaj sonrası)","Boya","Kalite (Boya sonrası)","Yarı Mamül","KM"})),IF(COUNT(G17:R17)=0,"Başlamadı",LOOKUP(2,1/(G17:R17=MAX(G17:R17)),{"Tasarımda","Ply Cutter'da","Üretimde","Kalitede (Üretim sonrası)","Talaşlıda","Kalitede (Talaşlı sonrası)","Montajda","Kalitede (Montaj sonrası)","Boyada","Kalitede (Boya sonrası)","Yarı Mamülde","KM'de"})))))) -> Kapandı – Yarı Mamül | AA17: =IF(OR(B17="",F17=""),"",IFERROR(IF(S17<>"",S17-F17,IF(T17<>"",T17-F17,TODAY()-F17)),"")) -> 3 | AD17: =IF(OR($B17="",NOT(ISNUMBER(G17))),"",IF(COUNTIF(H17:$T17,G17)>0,0,IF(COUNTIF($G17:$T17,">"&G17)=0,"",SMALL($G17:$T17,COUNTIF($G17:$T17,"<="&G17)+1)-G17))) | AE17: =IF(OR($B17="",NOT(ISNUMBER(H17))),"",IF(COUNTIF(I17:$T17,H17)>0,0,IF(COUNTIF($G17:$T17,">"&H17)=0,"",SMALL($G17:$T17,COUNTIF($G17:$T17,"<="&H17)+1)-H17))) | AF17: =IF(OR($B17="",NOT(ISNUMBER(I17))),"",IF(COUNTIF(J17:$T17,I17)>0,0,IF(COUNTIF($G17:$T17,">"&I17)=0,"",SMALL($G17:$T17,COUNTIF($G17:$T17,"<="&I17)+1)-I17))) -> 2 | AG17: =IF(OR($B17="",NOT(ISNUMBER(J17))),"",IF(COUNTIF(K17:$T17,J17)>0,0,IF(COUNTIF($G17:$T17,">"&J17)=0,"",SMALL($G17:$T17,COUNTIF($G17:$T17,"<="&J17)+1)-J17))) -> 1 | AH17: =IF(OR($B17="",NOT(ISNUMBER(K17))),"",IF(COUNTIF(L17:$T17,K17)>0,0,IF(COUNTIF($G17:$T17,">"&K17)=0,"",SMALL($G17:$T17,COUNTIF($G17:$T17,"<="&K17)+1)-K17))) | AI17: =IF(OR($B17="",NOT(ISNUMBER(L17))),"",IF(COUNTIF(M17:$T17,L17)>0,0,IF(COUNTIF($G17:$T17,">"&L17)=0,"",SMALL($G17:$T17,COUNTIF($G17:$T17,"<="&L17)+1)-L17))) | AJ17: =IF(OR($B17="",NOT(ISNUMBER(M17))),"",IF(COUNTIF(N17:$T17,M17)>0,0,IF(COUNTIF($G17:$T17,">"&M17)=0,"",SMALL($G17:$T17,COUNTIF($G17:$T17,"<="&M17)+1)-M17))) | AK17: =IF(OR($B17="",NOT(ISNUMBER(N17))),"",IF(COUNTIF(O17:$T17,N17)>0,0,IF(COUNTIF($G17:$T17,">"&N17)=0,"",SMALL($G17:$T17,COUNTIF($G17:$T17,"<="&N17)+1)-N17))) | ... AO17: =IF(OR($B17="",NOT(ISNUMBER(R17))),"",IF(COUNTIF(S17:$T17,R17)>0,0,IF(COUNTIF($G17:$T17,">"&R17)=0,"",SMALL($G17:$T17,COUNTIF($G17:$T17,"<="&R17)+1)-R17))) | AP17: =IF(OR($B17="",Z17="",Z17="Başlamadı",Z17="Sevk Edildi",Z17="Reworkte",LEFT(Z17,7)="Kapandı"),0,TODAY()-MAX($G17:$R17)) -> 0 | AQ17: =IF(AND(ISNUMBER(G17),ISNUMBER(AD17)),G17+AD17,"") | AR17: =IF(AND(ISNUMBER(H17),ISNUMBER(AE17)),H17+AE17,"") | AS17: =IF(AND(ISNUMBER(I17),ISNUMBER(AF17)),I17+AF17,"") -> 46290 | AT17: =IF(AND(ISNUMBER(J17),ISNUMBER(AG17)),J17+AG17,"") -> 46291 | AU17: =IF(AND(ISNUMBER(K17),ISNUMBER(AH17)),K17+AH17,"") | AV17: =IF(AND(ISNUMBER(L17),ISNUMBER(AI17)),L17+AI17,"") | AW17: =IF(AND(ISNUMBER(M17),ISNUMBER(AJ17)),M17+AJ17,"") | AX17: =IF(AND(ISNUMBER(N17),ISNUMBER(AK17)),N17+AK17,"") | ... BB17: =IF(AND(ISNUMBER(R17),ISNUMBER(AO17)),R17+AO17,"") | BC17: =IF(AND(S17="",T17=""),"",MIN(S17,T17)) -> 46291
A18: =IF(B18="","",ROW()-2) -> 16 | B18: M43001 | C18: SOM0001-B - 2 - SOM-KANATCIK ARTI EKSI LAY-UP | D18: =IFERROR(VALUE(TRIM(MID(C18,FIND(" - ",C18)+3,FIND(" - ",C18,FIND(" - ",C18)+3)-FIND(" - ",C18)-3))),"") -> 2 | E18: AYÇA GÖK | F18: 46288 | I18: 46288 | J18: 46291 | T18: 46291 | Z18: =IF(B18="","",IF(S18<>"","Sevk Edildi",IF(AND(X18<>"",Y18=""),"Reworkte",IF(T18<>"","Kapandı"&IF(COUNT(G18:R18)=0,""," – "&LOOKUP(2,1/(G18:R18=MAX(G18:R18)),{"Tasarım","Ply Cutter","Üretim","Kalite (Üretim sonrası)","Talaşlı","Kalite (Talaşlı sonrası)","Montaj","Kalite (Montaj sonrası)","Boya","Kalite (Boya sonrası)","Yarı Mamül","KM"})),IF(COUNT(G18:R18)=0,"Başlamadı",LOOKUP(2,1/(G18:R18=MAX(G18:R18)),{"Tasarımda","Ply Cutter'da","Üretimde","Kalitede (Üretim sonrası)","Talaşlıda","Kalitede (Talaşlı sonrası)","Montajda","Kalitede (Montaj sonrası)","Boyada","Kalitede (Boya sonrası)","Yarı Mamülde","KM'de"})))))) -> Kapandı – Kalite (Üretim sonrası) | AA18: =IF(OR(B18="",F18=""),"",IFERROR(IF(S18<>"",S18-F18,IF(T18<>"",T18-F18,TODAY()-F18)),"")) -> 3 | AD18: =IF(OR($B18="",NOT(ISNUMBER(G18))),"",IF(COUNTIF(H18:$T18,G18)>0,0,IF(COUNTIF($G18:$T18,">"&G18)=0,"",SMALL($G18:$T18,COUNTIF($G18:$T18,"<="&G18)+1)-G18))) | AE18: =IF(OR($B18="",NOT(ISNUMBER(H18))),"",IF(COUNTIF(I18:$T18,H18)>0,0,IF(COUNTIF($G18:$T18,">"&H18)=0,"",SMALL($G18:$T18,COUNTIF($G18:$T18,"<="&H18)+1)-H18))) | AF18: =IF(OR($B18="",NOT(ISNUMBER(I18))),"",IF(COUNTIF(J18:$T18,I18)>0,0,IF(COUNTIF($G18:$T18,">"&I18)=0,"",SMALL($G18:$T18,COUNTIF($G18:$T18,"<="&I18)+1)-I18))) -> 3 | AG18: =IF(OR($B18="",NOT(ISNUMBER(J18))),"",IF(COUNTIF(K18:$T18,J18)>0,0,IF(COUNTIF($G18:$T18,">"&J18)=0,"",SMALL($G18:$T18,COUNTIF($G18:$T18,"<="&J18)+1)-J18))) -> 0 | AH18: =IF(OR($B18="",NOT(ISNUMBER(K18))),"",IF(COUNTIF(L18:$T18,K18)>0,0,IF(COUNTIF($G18:$T18,">"&K18)=0,"",SMALL($G18:$T18,COUNTIF($G18:$T18,"<="&K18)+1)-K18))) | AI18: =IF(OR($B18="",NOT(ISNUMBER(L18))),"",IF(COUNTIF(M18:$T18,L18)>0,0,IF(COUNTIF($G18:$T18,">"&L18)=0,"",SMALL($G18:$T18,COUNTIF($G18:$T18,"<="&L18)+1)-L18))) | AJ18: =IF(OR($B18="",NOT(ISNUMBER(M18))),"",IF(COUNTIF(N18:$T18,M18)>0,0,IF(COUNTIF($G18:$T18,">"&M18)=0,"",SMALL($G18:$T18,COUNTIF($G18:$T18,"<="&M18)+1)-M18))) | AK18: =IF(OR($B18="",NOT(ISNUMBER(N18))),"",IF(COUNTIF(O18:$T18,N18)>0,0,IF(COUNTIF($G18:$T18,">"&N18)=0,"",SMALL($G18:$T18,COUNTIF($G18:$T18,"<="&N18)+1)-N18))) | ... AO18: =IF(OR($B18="",NOT(ISNUMBER(R18))),"",IF(COUNTIF(S18:$T18,R18)>0,0,IF(COUNTIF($G18:$T18,">"&R18)=0,"",SMALL($G18:$T18,COUNTIF($G18:$T18,"<="&R18)+1)-R18))) | AP18: =IF(OR($B18="",Z18="",Z18="Başlamadı",Z18="Sevk Edildi",Z18="Reworkte",LEFT(Z18,7)="Kapandı"),0,TODAY()-MAX($G18:$R18)) -> 0 | AQ18: =IF(AND(ISNUMBER(G18),ISNUMBER(AD18)),G18+AD18,"") | AR18: =IF(AND(ISNUMBER(H18),ISNUMBER(AE18)),H18+AE18,"") | AS18: =IF(AND(ISNUMBER(I18),ISNUMBER(AF18)),I18+AF18,"") -> 46291 | AT18: =IF(AND(ISNUMBER(J18),ISNUMBER(AG18)),J18+AG18,"") -> 46291 | AU18: =IF(AND(ISNUMBER(K18),ISNUMBER(AH18)),K18+AH18,"") | AV18: =IF(AND(ISNUMBER(L18),ISNUMBER(AI18)),L18+AI18,"") | AW18: =IF(AND(ISNUMBER(M18),ISNUMBER(AJ18)),M18+AJ18,"") | AX18: =IF(AND(ISNUMBER(N18),ISNUMBER(AK18)),N18+AK18,"") | ... BB18: =IF(AND(ISNUMBER(R18),ISNUMBER(AO18)),R18+AO18,"") | BC18: =IF(AND(S18="",T18=""),"",MIN(S18,T18)) -> 46291
A19: =IF(B19="","",ROW()-2) -> 17 | B19: M43002 | C19: MN-7914-0023-B - 1 - ACAR RADOM SERIM | D19: =IFERROR(VALUE(TRIM(MID(C19,FIND(" - ",C19)+3,FIND(" - ",C19,FIND(" - ",C19)+3)-FIND(" - ",C19)-3))),"") -> 1 | E19: AYÇA GÖK | F19: 46288 | I19: 46288 | J19: 46291 | Q19: 46293 | T19: 46293 | Z19: =IF(B19="","",IF(S19<>"","Sevk Edildi",IF(AND(X19<>"",Y19=""),"Reworkte",IF(T19<>"","Kapandı"&IF(COUNT(G19:R19)=0,""," – "&LOOKUP(2,1/(G19:R19=MAX(G19:R19)),{"Tasarım","Ply Cutter","Üretim","Kalite (Üretim sonrası)","Talaşlı","Kalite (Talaşlı sonrası)","Montaj","Kalite (Montaj sonrası)","Boya","Kalite (Boya sonrası)","Yarı Mamül","KM"})),IF(COUNT(G19:R19)=0,"Başlamadı",LOOKUP(2,1/(G19:R19=MAX(G19:R19)),{"Tasarımda","Ply Cutter'da","Üretimde","Kalitede (Üretim sonrası)","Talaşlıda","Kalitede (Talaşlı sonrası)","Montajda","Kalitede (Montaj sonrası)","Boyada","Kalitede (Boya sonrası)","Yarı Mamülde","KM'de"})))))) -> Kapandı – Yarı Mamül | AA19: =IF(OR(B19="",F19=""),"",IFERROR(IF(S19<>"",S19-F19,IF(T19<>"",T19-F19,TODAY()-F19)),"")) -> 5 | AD19: =IF(OR($B19="",NOT(ISNUMBER(G19))),"",IF(COUNTIF(H19:$T19,G19)>0,0,IF(COUNTIF($G19:$T19,">"&G19)=0,"",SMALL($G19:$T19,COUNTIF($G19:$T19,"<="&G19)+1)-G19))) | AE19: =IF(OR($B19="",NOT(ISNUMBER(H19))),"",IF(COUNTIF(I19:$T19,H19)>0,0,IF(COUNTIF($G19:$T19,">"&H19)=0,"",SMALL($G19:$T19,COUNTIF($G19:$T19,"<="&H19)+1)-H19))) | AF19: =IF(OR($B19="",NOT(ISNUMBER(I19))),"",IF(COUNTIF(J19:$T19,I19)>0,0,IF(COUNTIF($G19:$T19,">"&I19)=0,"",SMALL($G19:$T19,COUNTIF($G19:$T19,"<="&I19)+1)-I19))) -> 3 | AG19: =IF(OR($B19="",NOT(ISNUMBER(J19))),"",IF(COUNTIF(K19:$T19,J19)>0,0,IF(COUNTIF($G19:$T19,">"&J19)=0,"",SMALL($G19:$T19,COUNTIF($G19:$T19,"<="&J19)+1)-J19))) -> 2 | AH19: =IF(OR($B19="",NOT(ISNUMBER(K19))),"",IF(COUNTIF(L19:$T19,K19)>0,0,IF(COUNTIF($G19:$T19,">"&K19)=0,"",SMALL($G19:$T19,COUNTIF($G19:$T19,"<="&K19)+1)-K19))) | AI19: =IF(OR($B19="",NOT(ISNUMBER(L19))),"",IF(COUNTIF(M19:$T19,L19)>0,0,IF(COUNTIF($G19:$T19,">"&L19)=0,"",SMALL($G19:$T19,COUNTIF($G19:$T19,"<="&L19)+1)-L19))) | AJ19: =IF(OR($B19="",NOT(ISNUMBER(M19))),"",IF(COUNTIF(N19:$T19,M19)>0,0,IF(COUNTIF($G19:$T19,">"&M19)=0,"",SMALL($G19:$T19,COUNTIF($G19:$T19,"<="&M19)+1)-M19))) | AK19: =IF(OR($B19="",NOT(ISNUMBER(N19))),"",IF(COUNTIF(O19:$T19,N19)>0,0,IF(COUNTIF($G19:$T19,">"&N19)=0,"",SMALL($G19:$T19,COUNTIF($G19:$T19,"<="&N19)+1)-N19))) | ... AO19: =IF(OR($B19="",NOT(ISNUMBER(R19))),"",IF(COUNTIF(S19:$T19,R19)>0,0,IF(COUNTIF($G19:$T19,">"&R19)=0,"",SMALL($G19:$T19,COUNTIF($G19:$T19,"<="&R19)+1)-R19))) | AP19: =IF(OR($B19="",Z19="",Z19="Başlamadı",Z19="Sevk Edildi",Z19="Reworkte",LEFT(Z19,7)="Kapandı"),0,TODAY()-MAX($G19:$R19)) -> 0 | AQ19: =IF(AND(ISNUMBER(G19),ISNUMBER(AD19)),G19+AD19,"") | AR19: =IF(AND(ISNUMBER(H19),ISNUMBER(AE19)),H19+AE19,"") | AS19: =IF(AND(ISNUMBER(I19),ISNUMBER(AF19)),I19+AF19,"") -> 46291 | AT19: =IF(AND(ISNUMBER(J19),ISNUMBER(AG19)),J19+AG19,"") -> 46293 | AU19: =IF(AND(ISNUMBER(K19),ISNUMBER(AH19)),K19+AH19,"") | AV19: =IF(AND(ISNUMBER(L19),ISNUMBER(AI19)),L19+AI19,"") | AW19: =IF(AND(ISNUMBER(M19),ISNUMBER(AJ19)),M19+AJ19,"") | AX19: =IF(AND(ISNUMBER(N19),ISNUMBER(AK19)),N19+AK19,"") | ... BB19: =IF(AND(ISNUMBER(R19),ISNUMBER(AO19)),R19+AO19,"") | BC19: =IF(AND(S19="",T19=""),"",MIN(S19,T19)) -> 46293
